Workbook
Name C_VAL: COSTING!$M$4:$M$17
Name CODE_ING: COSTING!$L$4:$L$17
Name CUM_URG: 'SUPPLY-UR'!$M:$M
Name MEN_COD: MENU2!$A:$A
Name MEN_DES: MENU2!$B:$B
Name MEN_GMS: MENU2!$E:$E
Name MEN_QTY: MENU2!#REF!
Name MISC_DATE: #REF!
Name NativeTimeline_DATE: #N/A
Name SAL_AMT: #REF!
Name SAL_CAT: #REF!
Name SAL_DATE: #REF!
Name Slicer_Category: #N/A
Name SUM_DIS: 'SALES''26'!$H:$H
Name SUM_GRO: 'SALES''26'!$K:$K
Name SUM_GRS: 'SALES''26'!$E:$E
Name SUM_MISC: #REF!
Name SUM_NET: 'SALES''26'!$I:$I
Name SUM_PER: 'SALES''26'!$N:$N
Name SUM_PRO: 'SALES''26'!$A:$A
Name SUM_QTY: 'SALES''26'!$D:$D
Name SUP_AMT: #REF!
Name SUP_DATE: #REF!
Name SUP_NAME: #REF!
Name SUP_QTY: #REF!

Sheet MENU2
A1: MENU DATABASE
A3: CODE | B3: DESCRIPTION | E3: QTY
B4: DON BURI BOWLS
B5: CHICKEN
A6: CF_060 | B6: [DB] Oyakudon (Set A) | C6: DON BURI (CHICKEN) | E6: 2
A7: EGG | B7: [DB] Oyakudon (Set A) | C7: DON BURI (CHICKEN) | E7: 2
A8: TSS | B8: [DB] Oyakudon (Set A) | C8: DON BURI (CHICKEN) | E8: 130
A9: CF_060 | B9: [DB] Oyakudon (Set B) | C9: DON BURI (CHICKEN) | E9: 2
A10: EGG | B10: [DB] Oyakudon (Set B) | C10: DON BURI (CHICKEN) | E10: 2
A11: TSS | B11: [DB] Oyakudon (Set B) | C11: DON BURI (CHICKEN) | E11: 130
A12: KNI | B12: [DB] Oyakudon (Set B) | C12: DON BURI (CHICKEN) | E12: 0.25
A13: CAR | B13: [DB] Oyakudon (Set B) | C13: DON BURI (CHICKEN) | E13: 1
A14: CT_120 | B14: [DB] Karaagedon (Set A) | C14: DON BURI (CHICKEN) | E14: 1
A15: B+B | B15: [DB] Karaagedon (Set A) | C15: DON BURI (CHICKEN) | E15: 1
A16: CT_120 | B16: [DB] Karaagedon (Set B) | C16: DON BURI (CHICKEN) | E16: 1
A17: KNI | B17: [DB] Karaagedon (Set B) | C17: DON BURI (CHICKEN) | E17: 0.25
A18: ICT | B18: [DB] Karaagedon (Set B) | C18: DON BURI (CHICKEN)
A19: TSS | B19: [DB] Karaagedon (Set B) | C19: DON BURI (CHICKEN) | E19: 30
A20: CF_060 | B20: [DB] Shoyu Miso Buttered Chicken (Set A) | C20: DON BURI (CHICKEN) | E20: 2
A21: SHO | B21: [DB] Shoyu Miso Buttered Chicken (Set A) | C21: DON BURI (CHICKEN) | E21: 10
A22: CF_060 | B22: [DB] Torikatsu (Set A) | C22: DON BURI (CHICKEN) | E22: 2
A23: CF_060 | B23: [DB] Torikatsu (Set B) | E23: 2
A24: ICT | B24: [DB] Torikatsu (Set B) | E24: 1
A25: CF_060 | B25: [DB] Torikatsudon (Set A) | C25: DON BURI (CHICKEN) | E25: 2
A26: EGG | B26: [DB] Torikatsudon (Set A) | C26: DON BURI (CHICKEN) | E26: 2
A27: CF_060 | B27: [DB] Torikatsudon (Set B) | C27: STARDEALS | E27: 2
A28: TSS | B28: [DB] Torikatsudon (Set B) | C28: STARDEALS | E28: 130
A29: ICT | B29: [DB] Torikatsudon (Set B) | C29: STARDEALS | E29: 1
A30: EGG | B30: [DB] Torikatsudon (Set B) | C30: STARDEALS | E30: 2
A31: B+B | B31: [DB] Torikatsudon (Set B) | C31: STARDEALS | E31: 1
A32: CT_150 | B32: [DB] Chicken Terriyaki (Set B) | C32: DON BURI (CHICKEN) | E32: 1
A33: TER | B33: [DB] Chicken Terriyaki (Set B) | C33: DON BURI (CHICKEN) | E33: 1
A34: KNI | B34: [DB] Chicken Terriyaki (Set B) | C34: DON BURI (CHICKEN) | E34: 0.25
A35: ICT | B35: [DB] Chicken Terriyaki (Set B) | C35: DON BURI (CHICKEN) | E35: 1
A36: VDB | B36: [DB] Chicken Terriyaki (Set B) | C36: DON BURI (CHICKEN) | E36: 1
A37: CF_060 | B37: Chicken Misono Set A | E37: 2
A38: CF_060 | B38: [DB] Chicken Teppanyaki/Misono (Set A) | C38: DON BURI (CHICKEN) | E38: 2
A39: TEP | B39: [DB] Chicken Teppanyaki/Misono (Set A) | C39: DON BURI (CHICKEN) | E39: 1
A40: VDB | B40: [DB] Chicken Teppanyaki/Misono (Set A) | C40: DON BURI (CHICKEN) | E40: 1
A41: CF_040 | B41: [DB] Yakitori (Set A) | C41: DON BURI (CHICKEN) | E41: 3
...

Sheet SUPPLY-UR
A1: SUPPLY - UNIT RATES
B4: SUPPLIER | C4: PRODUCT | E4: QUANTITY | F4: UNIT | G4: Detailed Quantity | H4: UNIT RATE | I4: AMOUNT | K4: Wastage/ Fluctuation | L4: NET | M4: Unit Rate per gms | P4: =H28*1.3 -> 318.5
C6: Japanese Rice - Sakura | E6: 1 | F6: kg | H6: 80 | I6: =H6*E6 -> 80
C7: Cane Vinegar | E7: 1 | F7: bot | H7: 105
C8: Sugar | E8: 1 | F8: kg | H8: 90
B9: BANRI | C9: Gyoza Wrapper | E9: 1 | F9: pk | I9: =H9*E9 -> 0
B10: BANRI | C10: Ramen Noodles | E10: 1 | F10: kg | H10: 220 | I10: =H10*E10 -> 220 | K10: 0.2 | L10: =1000*(100%-K10) -> 800 | M10: =IFERROR(H10/L10,0) -> 0.275
B11: BANRI | C11: Shoyo Soy Sauce | E11: 1 | F11: bot | G11: 1000 | H11: 450 | I11: =H11*E11 -> 450 | K11: 0.25 | L11: =G11*(100%-K11) -> 750 | M11: =IFERROR(H11/L11,0) -> 0.6
B12: FIRST ENTERPRISES | C12: Sola | E12: 1 | F12: case | G12: 24 | H12: 1221.75 | I12: =H12*E12 -> 1221.75 | K12: 0 | L12: =G12*(100%-K12) -> 24 | M12: =IFERROR(H12/L12,0) -> 50.90625
B13: FIRST REGAL | C13: Palm Oil | E13: 1 | F13: can | G13: 18000 | H13: 1670 | I13: =H13*E13 -> 1670 | K13: 0.2 | L13: =G13*(100%-K13) -> 14400 | M13: =IFERROR(H13/L13,0) -> 0.11597222
B14: FRANCESCO | C14: Chicken Breast | D14: CHX | E14: 1 | F14: kg | G14: 1000 | H14: 295 | I14: =H14*E14 -> 295 | K14: 0.2 | L14: =1000*(100%-K14) -> 800 | M14: =IFERROR(H14/L14,0) -> 0.36875
B15: FRANCESCO | C15: Chicken Legs - boneless | D15: CHX | E15: 1 | F15: kg | G15: 1000 | H15: 280 | I15: =H15*E15 -> 280 | K15: 0.2 | L15: =1000*(100%-K15) -> 800 | M15: =IFERROR(H15/L15,0) -> 0.35
B16: FRANCESCO | C16: Nobashi | D16: NOB | E16: 1 | F16: pk | G16: 25 | H16: 325 | I16: =H16*E16 -> 325 | K16: 0.05 | L16: =G16*(100%-K16) -> 23.75 | M16: =IFERROR(H16/L16,0) -> 13.684211
B17: FRANCESCO | C17: PDT - shrimp | E17: 1 | F17: kg | G17: 48 | H17: 650 | I17: =H17*E17 -> 650 | K17: 0.25 | L17: =G17*(100%-K17) -> 36 | M17: =IFERROR(H17/L17,0) -> 18.055556
B18: FRANCESCO | C18: Salmon | E18: 1 | F18: kg | G18: 1000 | H18: 1200 | I18: =H18*E18 -> 1200 | K18: 0.65 | L18: =G18*(100%-K18) -> 350 | M18: =IFERROR(H18/L18,0) -> 3.4285714 | O18: =3.48+0.256 -> 3.736 | P18: 5.3 | Q18: =O18/P18 -> 0.70490566
B19: FRANCESCO | C19: Squid Tube | E19: 1 | F19: kg | G19: 1000 | H19: 290 | I19: =H19*E19 -> 290 | K19: 0.25 | L19: =G19*(100%-K19) -> 750 | M19: =IFERROR(H19/L19,0) -> 0.38666667
B20: FRANCESCO | C20: Tuna Steak | E20: 1 | F20: kg | G20: 1000 | H20: 520 | I20: =H20*E20 -> 520 | K20: 0.35 | L20: =G20*(100%-K20) -> 650 | M20: =IFERROR(H20/L20,0) -> 0.8
B21: HI-QRYS | C21: Rice | E21: 1 | F21: sack | G21: 25000 | H21: 1600 | I21: =H21*E21 -> 1600 | K21: 0 | L21: =G21*(100%-K21) -> 25000 | M21: =IFERROR(H21/L21,0) -> 0.064 | N21: 150 | O21: =M21*N21 -> 9.6 | P21: 1 CUP = 210 gms
B22: MJT GAS | C22: Gas | E22: 1 | F22: tank | G22: 22 | H22: 2134 | I22: =H22*E22 -> 2134 | K22: 0.25 | L22: =G22*(100%-K22) -> 16.5 | M22: =IFERROR(H22/L22,0) -> 129.33333
B23: SHOKURYOHIN | C23: Aonori | E23: 1 | F23: pk | G23: 500 | H23: 650 | I23: =H23*E23 -> 650 | K23: 0.25 | L23: =G23*(100%-K23) -> 375 | M23: =IFERROR(H23/L23,0) -> 1.7333333
B24: SHOKURYOHIN | C24: Baran | E24: 1 | F24: box | H24: 95 | I24: =H24*E24 -> 95 | K24: 0.2 | L24: =G24*(100%-K24) -> 0 | M24: =IFERROR(H24/L24,0) -> 0
B25: SHOKURYOHIN | C25: Benishoga | E25: 1 | F25: kg | H25: 230 | I25: =H25*E25 -> 230 | K25: 0.25 | L25: =G25*(100%-K25) -> 0 | M25: =IFERROR(H25/L25,0) -> 0 | O25: =2.5*O21 -> 24
B26: SHOKURYOHIN | C26: Chicken Breast | D26: CHX | E26: 1 | F26: kg | G26: 1000 | H26: 270 | I26: =H26*E26 -> 270 | K26: 0.2 | L26: =G26*(100%-K26) -> 800 | M26: =IFERROR(H26/L26,0) -> 0.3375 | P26: 0.4 | Q26: 0.35 | R26: 0.45
B27: SHOKURYOHIN | C27: Chicken Fillet - leg | D27: CHX | E27: 1 | F27: kg | G27: 1000 | H27: 390 | I27: =H27*E27 -> 390 | K27: 0.3 | L27: =G27*(100%-K27) -> 700 | M27: =IFERROR(H27/L27,0) -> 0.55714286 | N27: 150 | O27: =M27*N27 -> 83.571429 | P27: =$O$27*P26 -> 33.428571 | Q27: =$O$27*Q26 -> 29.25 | R27: =$O$27*R26 -> 37.607143 | S27: =SUBTOTAL(9,O27:R27) -> 0
B28: SHOKURYOHIN | C28: Chicken Legs - boneless | D28: CHX | E28: 1 | F28: kg | G28: 1000 | H28: 245 | I28: =H28*E28 -> 245 | K28: 0.3 | L28: =G28*(100%-K28) -> 700 | M28: =IFERROR(H28/L28,0) -> 0.35 | N28: 40 | O28: =M28*N28 -> 14 | P28: =O28*2.2 -> 30.8
B29: SHOKURYOHIN | C29: Curry Flakes | E29: 1 | F29: kg | G29: 1000 | H29: 475 | I29: =H29*E29 -> 475 | K29: 0.25 | L29: =G29*(100%-K29) -> 750 | M29: =IFERROR(H29/L29,0) -> 0.63333333 | O29: =2.5/O25 -> 0.10416667
B30: SHOKURYOHIN | C30: Ebiko | E30: 1 | F30: pk | G30: 500 | H30: 850 | I30: =H30*E30 -> 850 | K30: 0.08 | L30: =G30*(100%-K30) -> 460 | M30: =IFERROR(H30/L30,0) -> 1.8478261
B31: SHOKURYOHIN | C31: Gary Pink | E31: 1 | F31: kg | G31: 1000 | H31: 200 | I31: =H31*E31 -> 200 | K31: 0.2 | L31: =G31*(100%-K31) -> 800 | M31: =IFERROR(H31/L31,0) -> 0.25
B32: SHOKURYOHIN | C32: Hondashi - Mrutomo | E32: 1 | F32: kg | G32: 1000 | H32: 450 | I32: =H32*E32 -> 450 | K32: 0.2 | L32: =G32*(100%-K32) -> 800 | M32: =IFERROR(H32/L32,0) -> 0.5625
B33: SHOKURYOHIN | C33: Kani | D33: KAN | E33: 1 | F33: pk | G33: 30 | H33: 250 | I33: =H33*E33 -> 250 | K33: 0.15 | L33: =G33*(100%-K33) -> 25.5 | M33: =IFERROR(H33/L33,0) -> 9.8039216
B34: SHOKURYOHIN | C34: Katsubohi - Bunito Flakes | E34: 1 | F34: kg | G34: 1000 | H34: 850 | I34: =H34*E34 -> 850 | K34: 0.25 | L34: =G34*(100%-K34) -> 750 | M34: =IFERROR(H34/L34,0) -> 1.1333333
B35: SHOKURYOHIN | C35: Kikkoman - Yamasa | E35: 1 | F35: can | G35: 18000 | H35: 2700 | I35: =H35*E35 -> 2700 | K35: 0.3 | L35: =G35*(100%-K35) -> 12600 | M35: =IFERROR(H35/L35,0) -> 0.21428571
B36: SHOKURYOHIN | C36: Miso | E36: 1 | F36: pk | G36: 1000 | H36: 150 | I36: =H36*E36 -> 150 | K36: 0.2 | L36: =G36*(100%-K36) -> 800 | M36: =IFERROR(H36/L36,0) -> 0.1875
B37: SHOKURYOHIN | C37: Mayonaise | E37: 1 | F37: kg | G37: 1000 | H37: 360 | I37: =H37*E37 -> 360 | K37: 0.05 | L37: =G37*(100%-K37) -> 950 | M37: =IFERROR(H37/L37,0) -> 0.37894737
B38: SHOKURYOHIN | C38: Naruto | E38: 1 | F38: pk | G38: 160 | H38: 92 | I38: =H38*E38 -> 92 | K38: 0.25 | L38: =G38*(100%-K38) -> 120 | M38: =IFERROR(H38/L38,0) -> 0.76666667
B39: SHOKURYOHIN | C39: Nori sheet | E39: 1 | F39: pk | G39: 100 | H39: 700 | I39: =H39*E39 -> 700 | K39: 0.15 | L39: =G39*(100%-K39) -> 85 | M39: =IFERROR(H39/L39,0) -> 8.2352941
B40: SHOKURYOHIN | C40: Okonomiyaki | E40: 1 | F40: bot | G40: 2100 | H40: 475 | I40: =H40*E40 -> 475 | K40: 0.25 | L40: =G40*(100%-K40) -> 1575 | M40: =IFERROR(H40/L40,0) -> 0.3015873
B41: SHOKURYOHIN | C41: Orikaki | E41: 1 | F41: kg | G41: 1000 | H41: 1250 | I41: =H41*E41 -> 1250 | K41: 0.25 | L41: =G41*(100%-K41) -> 750 | M41: =IFERROR(H41/L41,0) -> 1.6666667
B42: SHOKURYOHIN | C42: Pork Belly | D42: PRK | E42: 1 | F42: kg | G42: 1000 | H42: 330 | I42: =H42*E42 -> 330 | K42: 0.45 | L42: =G42*(100%-K42) -> 550 | M42: =IFERROR(H42/L42,0) -> 0.6 | N42: 50 | O42: =M42*N42 -> 30
B43: SHOKURYOHIN | C43: Porkloin | D43: PRK | E43: 1 | F43: kg | G43: 1000 | H43: 290 | I43: =H43*E43 -> 290 | K43: 0.25 | L43: =G43*(100%-K43) -> 750 | M43: =IFERROR(H43/L43,0) -> 0.38666667
...

Sheet SUM-SALES25
R2: Sukiyaki Beef 50gms | S2: Ground Beef | T2: Sukiyaki Beef 30gms | U2: Ground Beef 60gms | V2: Porkloin 50gms | W2: Porkloin 60gms | X2: Porkloin 20gms | Y2: Pork Belly 60gms | Z2: Pork Belly 120gms | AA2: Chicken Fillet 40gms | AB2: Chicken Fillet 50gms | AC2: Chicken Fillet 60gms | AD2: Chicken Thigh 120gms | AE2: Chicken Thigh 150gms | AG2: Tuna | AH2: Salmon | AI2: Squid | AJ2: Squid 10 | AM2: Kani | AN2: Nobashi | AO2: Shrimp | AP2: Gyoza | AQ2: Tempura Sauce | AR2: Teppanyaki Sauce | AS2: Terriyaki Sauce | AT2: Marusen/ Ebara | AU2: Shoyo Sauce | AV2: Sushi Rice | AW2: Okonomiyaki Sauce | AX2: Ramen Noodle | AY2: Egg Noodle | AZ2: Egg | BA2: Breaded+ Bater | BB2: Benishoga | BC2: All Purpose Flour | BD2: Tufo | BE2: Ice Tea | BF2: Mushroom | BG2: Mushroom Okonomiyaki | BH2: M&M Vegetables | BI2: Donburi Vegetables | BJ2: REG. Vegetables | BK2: Vegetabales Okonomiyaki | BL2: Moyashi | BM2: Cucumber | BN2: Cooking Oil | BO2: TOTAL | BQ2: PORKLOIN | BR2: SUKIYAKI BEEF | BS2: GROUND BEEF | BT2: PORK | BU2: CHICKEN FILLET | BV2: CHICKEN BREAST | BW2: CHICKKEN THIGH
A3: Category | B3: (All) | R3: =R5*50 -> 100 | S3: =S5*50 -> 0 | T3: =T5*30 -> 0 | U3: =U5*60 -> 0 | V3: =V5*50 -> 0 | W3: =W5*60 -> 0 | X3: =X5*20 -> 0 | Y3: =Y5*60 -> 120 | Z3: =Z5*120 -> 0 | AA3: =AA5*40 -> 0 | AB3: =AB5*50 -> 0 | AC3: =AC5*60 -> 120 | AD3: =AD5*120 -> 120 | AE3: =AE5*150 -> 0 | AF3: =AF5*150 -> 0 | BQ3: PL | BR3: SB | BS3: GB | BT3: PB | BU3: CF | BV3: CB | BW3: CT
R4: SB_050 | S4: GB_050 | T4: SB_030 | U4: GB_060 | V4: PL_050 | W4: PL_060 | X4: PL_020 | Y4: PB_060 | Z4: PB_120 | AA4: CF_040 | AB4: CF_050 | AC4: CF_060 | AD4: CT_120 | AE4: CT_150 | AG4: TUN | AH4: SAL | AI4: SQD | AJ4: SQD_10 | AK4: SQD_15 | AL4: SQD_20 | AM4: KNI | AN4: EBI | AO4: PDT | AP4: GZA | AQ4: TSS | AR4: TEP | AS4: TER | AT4: MZN | AU4: SHO | AV4: SUS | AW4: OKO | AX4: NOD | AY4: ENOD | AZ4: EGG | BA4: B+B | BB4: BSG | BC4: APF | BD4: TUF | BE4: ICT | BF4: MUS | BG4: MUO | BH4: VMM | BI4: VDB | BJ4: VRG | BK4: VOK | BL4: VMO | BM4: CUC | BN4: OIL
B5: Sum of Net sales | C5: Sum of Items sold | Q5: Sum of Items sold | R5: =SUM(R6:R223) -> 2 | S5: =SUM(S6:S223) -> 0 | T5: =SUM(T6:T223) -> 0 | U5: =SUM(U6:U223) -> 0 | V5: =SUM(V6:V223) -> 0 | W5: =SUM(W6:W223) -> 0 | X5: =SUM(X6:X223) -> 0 | Y5: =SUM(Y6:Y223) -> 2 | ... AE5: =SUM(AE6:AE223) -> 0 | AG5: =SUM(AG6:AG223) -> 60 | AH5: =SUM(AH6:AH223) -> 80 | AI5: =SUM(AI6:AI223) -> 20 | AJ5: =SUM(AJ6:AJ223) -> 1 | AK5: =SUM(AK6:AK223) -> 0 | AL5: =SUM(AL6:AL223) -> 0 | AM5: =SUM(AM6:AM223) -> 3.25 | AN5: =SUM(AN6:AN223) -> 2 | ... BN5: =SUM(BN6:BN223) -> 0
A6: [DB] Crispy Chicken w/ Egg (Set B) | B6: 345 | C6: 1 | Q6: 1 | R6: {=IFERROR(_xlfn.XLOOKUP($A6&R$4,MEN_DES&MEN_COD,MEN_GMS),0)} -> 0 | S6: {=IFERROR(_xlfn.XLOOKUP($A6&S$4,MEN_DES&MEN_COD,MEN_GMS),0)*$Q6} -> 0 | T6: {=IFERROR(_xlfn.XLOOKUP($A6&T$4,MEN_DES&MEN_COD,MEN_GMS),0)*$Q6} -> 0 | U6: {=IFERROR(_xlfn.XLOOKUP($A6&U$4,MEN_DES&MEN_COD,MEN_GMS),0)*$Q6} -> 0 | V6: {=IFERROR(_xlfn.XLOOKUP($A6&V$4,MEN_DES&MEN_COD,MEN_GMS),0)*$Q6} -> 0 | W6: {=IFERROR(_xlfn.XLOOKUP($A6&W$4,MEN_DES&MEN_COD,MEN_GMS),0)*$Q6} -> 0 | X6: {=IFERROR(_xlfn.XLOOKUP($A6&X$4,MEN_DES&MEN_COD,MEN_GMS),0)*$Q6} -> 0 | Y6: {=IFERROR(_xlfn.XLOOKUP($A6&Y$4,MEN_DES&MEN_COD,MEN_GMS),0)*$Q6} -> 0 | Z6: {=IFERROR(_xlfn.XLOOKUP($A6&Z$4,MEN_DES&MEN_COD,MEN_GMS),0)*$Q6} -> 0 | ... AE6: {=IFERROR(_xlfn.XLOOKUP($A6&AE$4,MEN_DES&MEN_COD,MEN_GMS),0)*$Q6} -> 0 | AG6: {=IFERROR(_xlfn.XLOOKUP($A6&AG$4,MEN_DES&MEN_COD,MEN_GMS),0)*$Q6} -> 0 | AH6: {=IFERROR(_xlfn.XLOOKUP($A6&AH$4,MEN_DES&MEN_COD,MEN_GMS),0)*$Q6} -> 0 | AI6: {=IFERROR(_xlfn.XLOOKUP($A6&AI$4,MEN_DES&MEN_COD,MEN_GMS),0)*$Q6} -> 0 | AJ6: {=IFERROR(_xlfn.XLOOKUP($A6&AJ$4,MEN_DES&MEN_COD,MEN_GMS),0)*$Q6} -> 0 | AK6: {=IFERROR(_xlfn.XLOOKUP($A6&AK$4,MEN_DES&MEN_COD,MEN_GMS),0)*$Q6} -> 0 | AL6: {=IFERROR(_xlfn.XLOOKUP($A6&AL$4,MEN_DES&MEN_COD,MEN_GMS),0)*$Q6} -> 0 | AM6: {=IFERROR(_xlfn.XLOOKUP($A6&AM$4,MEN_DES&MEN_COD,MEN_GMS),0)*$Q6} -> 0.25 | AN6: {=IFERROR(_xlfn.XLOOKUP($A6&AN$4,MEN_DES&MEN_COD,MEN_GMS),0)*$Q6} -> 0 | ... BN6: {=IFERROR(_xlfn.XLOOKUP($A6&BN$4,MEN_DES&MEN_COD,MEN_GMS),0)*$Q6} -> 0 | BO6: =SUM(R6:BN6) -> 2.25
A7: [DS] Coke/Sprite/Royal/Rootbeer | B7: 88 | C7: 1 | Q7: 1 | R7: {=IFERROR(_xlfn.XLOOKUP($A7&R$4,MEN_DES&MEN_COD,MEN_GMS),0)} -> 0 | S7: {=IFERROR(_xlfn.XLOOKUP($A7&S$4,MEN_DES&MEN_COD,MEN_GMS),0)*$Q7} -> 0 | T7: {=IFERROR(_xlfn.XLOOKUP($A7&T$4,MEN_DES&MEN_COD,MEN_GMS),0)*$Q7} -> 0 | U7: {=IFERROR(_xlfn.XLOOKUP($A7&U$4,MEN_DES&MEN_COD,MEN_GMS),0)*$Q7} -> 0 | V7: {=IFERROR(_xlfn.XLOOKUP($A7&V$4,MEN_DES&MEN_COD,MEN_GMS),0)*$Q7} -> 0 | W7: {=IFERROR(_xlfn.XLOOKUP($A7&W$4,MEN_DES&MEN_COD,MEN_GMS),0)*$Q7} -> 0 | X7: {=IFERROR(_xlfn.XLOOKUP($A7&X$4,MEN_DES&MEN_COD,MEN_GMS),0)*$Q7} -> 0 | Y7: {=IFERROR(_xlfn.XLOOKUP($A7&Y$4,MEN_DES&MEN_COD,MEN_GMS),0)*$Q7} -> 0 | Z7: {=IFERROR(_xlfn.XLOOKUP($A7&Z$4,MEN_DES&MEN_COD,MEN_GMS),0)*$Q7} -> 0 | ... AE7: {=IFERROR(_xlfn.XLOOKUP($A7&AE$4,MEN_DES&MEN_COD,MEN_GMS),0)*$Q7} -> 0 | AG7: {=IFERROR(_xlfn.XLOOKUP($A7&AG$4,MEN_DES&MEN_COD,MEN_GMS),0)*$Q7} -> 0 | AH7: {=IFERROR(_xlfn.XLOOKUP($A7&AH$4,MEN_DES&MEN_COD,MEN_GMS),0)*$Q7} -> 0 | AI7: {=IFERROR(_xlfn.XLOOKUP($A7&AI$4,MEN_DES&MEN_COD,MEN_GMS),0)*$Q7} -> 0 | AJ7: {=IFERROR(_xlfn.XLOOKUP($A7&AJ$4,MEN_DES&MEN_COD,MEN_GMS),0)*$Q7} -> 0 | AK7: {=IFERROR(_xlfn.XLOOKUP($A7&AK$4,MEN_DES&MEN_COD,MEN_GMS),0)*$Q7} -> 0 | AL7: {=IFERROR(_xlfn.XLOOKUP($A7&AL$4,MEN_DES&MEN_COD,MEN_GMS),0)*$Q7} -> 0 | AM7: {=IFERROR(_xlfn.XLOOKUP($A7&AM$4,MEN_DES&MEN_COD,MEN_GMS),0)*$Q7} -> 0 | AN7: {=IFERROR(_xlfn.XLOOKUP($A7&AN$4,MEN_DES&MEN_COD,MEN_GMS),0)*$Q7} -> 0 | ... BN7: {=IFERROR(_xlfn.XLOOKUP($A7&BN$4,MEN_DES&MEN_COD,MEN_GMS),0)*$Q7} -> 0 | BO7: =SUM(R7:BN7) -> 0
A8: [DS] Sola | B8: 118 | C8: 1 | Q8: 1 | R8: {=IFERROR(_xlfn.XLOOKUP($A8&R$4,MEN_DES&MEN_COD,MEN_GMS),0)*$Q8} -> 0 | S8: {=IFERROR(_xlfn.XLOOKUP($A8&S$4,MEN_DES&MEN_COD,MEN_GMS),0)*$Q8} -> 0 | T8: {=IFERROR(_xlfn.XLOOKUP($A8&T$4,MEN_DES&MEN_COD,MEN_GMS),0)*$Q8} -> 0 | U8: {=IFERROR(_xlfn.XLOOKUP($A8&U$4,MEN_DES&MEN_COD,MEN_GMS),0)*$Q8} -> 0 | V8: {=IFERROR(_xlfn.XLOOKUP($A8&V$4,MEN_DES&MEN_COD,MEN_GMS),0)*$Q8} -> 0 | W8: {=IFERROR(_xlfn.XLOOKUP($A8&W$4,MEN_DES&MEN_COD,MEN_GMS),0)*$Q8} -> 0 | X8: {=IFERROR(_xlfn.XLOOKUP($A8&X$4,MEN_DES&MEN_COD,MEN_GMS),0)*$Q8} -> 0 | Y8: {=IFERROR(_xlfn.XLOOKUP($A8&Y$4,MEN_DES&MEN_COD,MEN_GMS),0)*$Q8} -> 0 | ... AE8: {=IFERROR(_xlfn.XLOOKUP($A8&AE$4,MEN_DES&MEN_COD,MEN_GMS),0)*$Q8} -> 0 | AG8: {=IFERROR(_xlfn.XLOOKUP($A8&AG$4,MEN_DES&MEN_COD,MEN_GMS),0)*$Q8} -> 0 | AH8: {=IFERROR(_xlfn.XLOOKUP($A8&AH$4,MEN_DES&MEN_COD,MEN_GMS),0)*$Q8} -> 0 | AI8: {=IFERROR(_xlfn.XLOOKUP($A8&AI$4,MEN_DES&MEN_COD,MEN_GMS),0)*$Q8} -> 0 | AJ8: {=IFERROR(_xlfn.XLOOKUP($A8&AJ$4,MEN_DES&MEN_COD,MEN_GMS),0)*$Q8} -> 0 | AK8: {=IFERROR(_xlfn.XLOOKUP($A8&AK$4,MEN_DES&MEN_COD,MEN_GMS),0)*$Q8} -> 0 | AL8: {=IFERROR(_xlfn.XLOOKUP($A8&AL$4,MEN_DES&MEN_COD,MEN_GMS),0)*$Q8} -> 0 | AM8: {=IFERROR(_xlfn.XLOOKUP($A8&AM$4,MEN_DES&MEN_COD,MEN_GMS),0)*$Q8} -> 0 | AN8: {=IFERROR(_xlfn.XLOOKUP($A8&AN$4,MEN_DES&MEN_COD,MEN_GMS),0)*$Q8} -> 0 | ... BN8: {=IFERROR(_xlfn.XLOOKUP($A8&BN$4,MEN_DES&MEN_COD,MEN_GMS),0)*$Q8} -> 0 | BO8: =SUM(R8:BN8) -> 0
A9: [MM] SF w/ Tuna & Salmon Sashimi & Ebi Tempura | B9: 310 | C9: 1 | Q9: 1 | R9: {=IFERROR(_xlfn.XLOOKUP($A9&R$4,MEN_DES&MEN_COD,MEN_GMS),0)*$Q9} -> 0 | S9: {=IFERROR(_xlfn.XLOOKUP($A9&S$4,MEN_DES&MEN_COD,MEN_GMS),0)*$Q9} -> 0 | T9: {=IFERROR(_xlfn.XLOOKUP($A9&T$4,MEN_DES&MEN_COD,MEN_GMS),0)*$Q9} -> 0 | U9: {=IFERROR(_xlfn.XLOOKUP($A9&U$4,MEN_DES&MEN_COD,MEN_GMS),0)*$Q9} -> 0 | V9: {=IFERROR(_xlfn.XLOOKUP($A9&V$4,MEN_DES&MEN_COD,MEN_GMS),0)*$Q9} -> 0 | W9: {=IFERROR(_xlfn.XLOOKUP($A9&W$4,MEN_DES&MEN_COD,MEN_GMS),0)*$Q9} -> 0 | X9: {=IFERROR(_xlfn.XLOOKUP($A9&X$4,MEN_DES&MEN_COD,MEN_GMS),0)*$Q9} -> 0 | Y9: {=IFERROR(_xlfn.XLOOKUP($A9&Y$4,MEN_DES&MEN_COD,MEN_GMS),0)*$Q9} -> 0 | ... AE9: {=IFERROR(_xlfn.XLOOKUP($A9&AE$4,MEN_DES&MEN_COD,MEN_GMS),0)*$Q9} -> 0 | AG9: {=IFERROR(_xlfn.XLOOKUP($A9&AG$4,MEN_DES&MEN_COD,MEN_GMS),0)*$Q9} -> 30 | AH9: {=IFERROR(_xlfn.XLOOKUP($A9&AH$4,MEN_DES&MEN_COD,MEN_GMS),0)*$Q9} -> 30 | AI9: {=IFERROR(_xlfn.XLOOKUP($A9&AI$4,MEN_DES&MEN_COD,MEN_GMS),0)*$Q9} -> 0 | AJ9: {=IFERROR(_xlfn.XLOOKUP($A9&AJ$4,MEN_DES&MEN_COD,MEN_GMS),0)*$Q9} -> 1 | AK9: {=IFERROR(_xlfn.XLOOKUP($A9&AK$4,MEN_DES&MEN_COD,MEN_GMS),0)*$Q9} -> 0 | AL9: {=IFERROR(_xlfn.XLOOKUP($A9&AL$4,MEN_DES&MEN_COD,MEN_GMS),0)*$Q9} -> 0 | AM9: {=IFERROR(_xlfn.XLOOKUP($A9&AM$4,MEN_DES&MEN_COD,MEN_GMS),0)*$Q9} -> 0 | AN9: {=IFERROR(_xlfn.XLOOKUP($A9&AN$4,MEN_DES&MEN_COD,MEN_GMS),0)*$Q9} -> 2 | ... BN9: {=IFERROR(_xlfn.XLOOKUP($A9&BN$4,MEN_DES&MEN_COD,MEN_GMS),0)*$Q9} -> 0 | BO9: =SUM(R9:BN9) -> 96
A10: [MR] California Maki | B10: 570 | C10: 3 | Q10: 3 | R10: {=IFERROR(_xlfn.XLOOKUP($A10&R$4,MEN_DES&MEN_COD,MEN_GMS),0)*$Q10} -> 0 | S10: {=IFERROR(_xlfn.XLOOKUP($A10&S$4,MEN_DES&MEN_COD,MEN_GMS),0)*$Q10} -> 0 | T10: {=IFERROR(_xlfn.XLOOKUP($A10&T$4,MEN_DES&MEN_COD,MEN_GMS),0)*$Q10} -> 0 | U10: {=IFERROR(_xlfn.XLOOKUP($A10&U$4,MEN_DES&MEN_COD,MEN_GMS),0)*$Q10} -> 0 | V10: {=IFERROR(_xlfn.XLOOKUP($A10&V$4,MEN_DES&MEN_COD,MEN_GMS),0)*$Q10} -> 0 | W10: {=IFERROR(_xlfn.XLOOKUP($A10&W$4,MEN_DES&MEN_COD,MEN_GMS),0)*$Q10} -> 0 | X10: {=IFERROR(_xlfn.XLOOKUP($A10&X$4,MEN_DES&MEN_COD,MEN_GMS),0)*$Q10} -> 0 | Y10: {=IFERROR(_xlfn.XLOOKUP($A10&Y$4,MEN_DES&MEN_COD,MEN_GMS),0)*$Q10} -> 0 | ... AE10: {=IFERROR(_xlfn.XLOOKUP($A10&AE$4,MEN_DES&MEN_COD,MEN_GMS),0)*$Q10} -> 0 | AG10: {=IFERROR(_xlfn.XLOOKUP($A10&AG$4,MEN_DES&MEN_COD,MEN_GMS),0)*$Q10} -> 0 | AH10: {=IFERROR(_xlfn.XLOOKUP($A10&AH$4,MEN_DES&MEN_COD,MEN_GMS),0)*$Q10} -> 0 | AI10: {=IFERROR(_xlfn.XLOOKUP($A10&AI$4,MEN_DES&MEN_COD,MEN_GMS),0)*$Q10} -> 0 | AJ10: {=IFERROR(_xlfn.XLOOKUP($A10&AJ$4,MEN_DES&MEN_COD,MEN_GMS),0)*$Q10} -> 0 | AK10: {=IFERROR(_xlfn.XLOOKUP($A10&AK$4,MEN_DES&MEN_COD,MEN_GMS),0)*$Q10} -> 0 | AL10: {=IFERROR(_xlfn.XLOOKUP($A10&AL$4,MEN_DES&MEN_COD,MEN_GMS),0)*$Q10} -> 0 | AM10: {=IFERROR(_xlfn.XLOOKUP($A10&AM$4,MEN_DES&MEN_COD,MEN_GMS),0)*$Q10} -> 3 | AN10: {=IFERROR(_xlfn.XLOOKUP($A10&AN$4,MEN_DES&MEN_COD,MEN_GMS),0)*$Q10} -> 0 | ... BN10: {=IFERROR(_xlfn.XLOOKUP($A10&BN$4,MEN_DES&MEN_COD,MEN_GMS),0)*$Q10} -> 0 | BO10: =SUM(R10:BN10) -> 370.5
A11: [MR] Salmon Spicy | B11: 330 | C11: 1 | Q11: 1 | R11: {=IFERROR(_xlfn.XLOOKUP($A11&R$4,MEN_DES&MEN_COD,MEN_GMS),0)*$Q11} -> 0 | S11: {=IFERROR(_xlfn.XLOOKUP($A11&S$4,MEN_DES&MEN_COD,MEN_GMS),0)*$Q11} -> 0 | T11: {=IFERROR(_xlfn.XLOOKUP($A11&T$4,MEN_DES&MEN_COD,MEN_GMS),0)*$Q11} -> 0 | U11: {=IFERROR(_xlfn.XLOOKUP($A11&U$4,MEN_DES&MEN_COD,MEN_GMS),0)*$Q11} -> 0 | V11: {=IFERROR(_xlfn.XLOOKUP($A11&V$4,MEN_DES&MEN_COD,MEN_GMS),0)*$Q11} -> 0 | W11: {=IFERROR(_xlfn.XLOOKUP($A11&W$4,MEN_DES&MEN_COD,MEN_GMS),0)*$Q11} -> 0 | X11: {=IFERROR(_xlfn.XLOOKUP($A11&X$4,MEN_DES&MEN_COD,MEN_GMS),0)*$Q11} -> 0 | Y11: {=IFERROR(_xlfn.XLOOKUP($A11&Y$4,MEN_DES&MEN_COD,MEN_GMS),0)*$Q11} -> 0 | ... AE11: {=IFERROR(_xlfn.XLOOKUP($A11&AE$4,MEN_DES&MEN_COD,MEN_GMS),0)*$Q11} -> 0 | AG11: {=IFERROR(_xlfn.XLOOKUP($A11&AG$4,MEN_DES&MEN_COD,MEN_GMS),0)*$Q11} -> 0 | AH11: {=IFERROR(_xlfn.XLOOKUP($A11&AH$4,MEN_DES&MEN_COD,MEN_GMS),0)*$Q11} -> 50 | AI11: {=IFERROR(_xlfn.XLOOKUP($A11&AI$4,MEN_DES&MEN_COD,MEN_GMS),0)*$Q11} -> 0 | AJ11: {=IFERROR(_xlfn.XLOOKUP($A11&AJ$4,MEN_DES&MEN_COD,MEN_GMS),0)*$Q11} -> 0 | AK11: {=IFERROR(_xlfn.XLOOKUP($A11&AK$4,MEN_DES&MEN_COD,MEN_GMS),0)*$Q11} -> 0 | AL11: {=IFERROR(_xlfn.XLOOKUP($A11&AL$4,MEN_DES&MEN_COD,MEN_GMS),0)*$Q11} -> 0 | AM11: {=IFERROR(_xlfn.XLOOKUP($A11&AM$4,MEN_DES&MEN_COD,MEN_GMS),0)*$Q11} -> 0 | AN11: {=IFERROR(_xlfn.XLOOKUP($A11&AN$4,MEN_DES&MEN_COD,MEN_GMS),0)*$Q11} -> 0 | ... BN11: {=IFERROR(_xlfn.XLOOKUP($A11&BN$4,MEN_DES&MEN_COD,MEN_GMS),0)*$Q11} -> 0 | BO11: =SUM(R11:BN11) -> 150
A12: [PR] 4pcs Gyoza | B12: 173.38 | C12: 1 | Q12: 1 | R12: {=IFERROR(_xlfn.XLOOKUP($A12&R$4,MEN_DES&MEN_COD,MEN_GMS),0)*$Q12} -> 0 | S12: {=IFERROR(_xlfn.XLOOKUP($A12&S$4,MEN_DES&MEN_COD,MEN_GMS),0)*$Q12} -> 0 | T12: {=IFERROR(_xlfn.XLOOKUP($A12&T$4,MEN_DES&MEN_COD,MEN_GMS),0)*$Q12} -> 0 | U12: {=IFERROR(_xlfn.XLOOKUP($A12&U$4,MEN_DES&MEN_COD,MEN_GMS),0)*$Q12} -> 0 | V12: {=IFERROR(_xlfn.XLOOKUP($A12&V$4,MEN_DES&MEN_COD,MEN_GMS),0)*$Q12} -> 0 | W12: {=IFERROR(_xlfn.XLOOKUP($A12&W$4,MEN_DES&MEN_COD,MEN_GMS),0)*$Q12} -> 0 | X12: {=IFERROR(_xlfn.XLOOKUP($A12&X$4,MEN_DES&MEN_COD,MEN_GMS),0)*$Q12} -> 0 | Y12: {=IFERROR(_xlfn.XLOOKUP($A12&Y$4,MEN_DES&MEN_COD,MEN_GMS),0)*$Q12} -> 0 | ... AE12: {=IFERROR(_xlfn.XLOOKUP($A12&AE$4,MEN_DES&MEN_COD,MEN_GMS),0)*$Q12} -> 0 | AG12: {=IFERROR(_xlfn.XLOOKUP($A12&AG$4,MEN_DES&MEN_COD,MEN_GMS),0)*$Q12} -> 0 | AH12: {=IFERROR(_xlfn.XLOOKUP($A12&AH$4,MEN_DES&MEN_COD,MEN_GMS),0)*$Q12} -> 0 | AI12: {=IFERROR(_xlfn.XLOOKUP($A12&AI$4,MEN_DES&MEN_COD,MEN_GMS),0)*$Q12} -> 0 | AJ12: {=IFERROR(_xlfn.XLOOKUP($A12&AJ$4,MEN_DES&MEN_COD,MEN_GMS),0)*$Q12} -> 0 | AK12: {=IFERROR(_xlfn.XLOOKUP($A12&AK$4,MEN_DES&MEN_COD,MEN_GMS),0)*$Q12} -> 0 | AL12: {=IFERROR(_xlfn.XLOOKUP($A12&AL$4,MEN_DES&MEN_COD,MEN_GMS),0)*$Q12} -> 0 | AM12: {=IFERROR(_xlfn.XLOOKUP($A12&AM$4,MEN_DES&MEN_COD,MEN_GMS),0)*$Q12} -> 0 | AN12: {=IFERROR(_xlfn.XLOOKUP($A12&AN$4,MEN_DES&MEN_COD,MEN_GMS),0)*$Q12} -> 0 | ... BN12: {=IFERROR(_xlfn.XLOOKUP($A12&BN$4,MEN_DES&MEN_COD,MEN_GMS),0)*$Q12} -> 0 | BO12: =SUM(R12:BN12) -> 0
A13: [PR] Chicken Misono | B13: 159 | C13: 1 | Q13: 1 | R13: {=IFERROR(_xlfn.XLOOKUP($A13&R$4,MEN_DES&MEN_COD,MEN_GMS),0)*$Q13} -> 0 | S13: {=IFERROR(_xlfn.XLOOKUP($A13&S$4,MEN_DES&MEN_COD,MEN_GMS),0)*$Q13} -> 0 | T13: {=IFERROR(_xlfn.XLOOKUP($A13&T$4,MEN_DES&MEN_COD,MEN_GMS),0)*$Q13} -> 0 | U13: {=IFERROR(_xlfn.XLOOKUP($A13&U$4,MEN_DES&MEN_COD,MEN_GMS),0)*$Q13} -> 0 | V13: {=IFERROR(_xlfn.XLOOKUP($A13&V$4,MEN_DES&MEN_COD,MEN_GMS),0)*$Q13} -> 0 | W13: {=IFERROR(_xlfn.XLOOKUP($A13&W$4,MEN_DES&MEN_COD,MEN_GMS),0)*$Q13} -> 0 | X13: {=IFERROR(_xlfn.XLOOKUP($A13&X$4,MEN_DES&MEN_COD,MEN_GMS),0)*$Q13} -> 0 | Y13: {=IFERROR(_xlfn.XLOOKUP($A13&Y$4,MEN_DES&MEN_COD,MEN_GMS),0)*$Q13} -> 0 | ... AE13: {=IFERROR(_xlfn.XLOOKUP($A13&AE$4,MEN_DES&MEN_COD,MEN_GMS),0)*$Q13} -> 0 | AG13: {=IFERROR(_xlfn.XLOOKUP($A13&AG$4,MEN_DES&MEN_COD,MEN_GMS),0)*$Q13} -> 0 | AH13: {=IFERROR(_xlfn.XLOOKUP($A13&AH$4,MEN_DES&MEN_COD,MEN_GMS),0)*$Q13} -> 0 | AI13: {=IFERROR(_xlfn.XLOOKUP($A13&AI$4,MEN_DES&MEN_COD,MEN_GMS),0)*$Q13} -> 0 | AJ13: {=IFERROR(_xlfn.XLOOKUP($A13&AJ$4,MEN_DES&MEN_COD,MEN_GMS),0)*$Q13} -> 0 | AK13: {=IFERROR(_xlfn.XLOOKUP($A13&AK$4,MEN_DES&MEN_COD,MEN_GMS),0)*$Q13} -> 0 | AL13: {=IFERROR(_xlfn.XLOOKUP($A13&AL$4,MEN_DES&MEN_COD,MEN_GMS),0)*$Q13} -> 0 | AM13: {=IFERROR(_xlfn.XLOOKUP($A13&AM$4,MEN_DES&MEN_COD,MEN_GMS),0)*$Q13} -> 0 | AN13: {=IFERROR(_xlfn.XLOOKUP($A13&AN$4,MEN_DES&MEN_COD,MEN_GMS),0)*$Q13} -> 0 | ... BN13: {=IFERROR(_xlfn.XLOOKUP($A13&BN$4,MEN_DES&MEN_COD,MEN_GMS),0)*$Q13} -> 0 | BO13: =SUM(R13:BN13) -> 3
A14: [PR] Okonomiyaki Buttered Chicken | B14: 209 | C14: 1 | Q14: 1 | R14: {=IFERROR(_xlfn.XLOOKUP($A14&R$4,MEN_DES&MEN_COD,MEN_GMS),0)*$Q14} -> 0 | S14: {=IFERROR(_xlfn.XLOOKUP($A14&S$4,MEN_DES&MEN_COD,MEN_GMS),0)*$Q14} -> 0 | T14: {=IFERROR(_xlfn.XLOOKUP($A14&T$4,MEN_DES&MEN_COD,MEN_GMS),0)*$Q14} -> 0 | U14: {=IFERROR(_xlfn.XLOOKUP($A14&U$4,MEN_DES&MEN_COD,MEN_GMS),0)*$Q14} -> 0 | V14: {=IFERROR(_xlfn.XLOOKUP($A14&V$4,MEN_DES&MEN_COD,MEN_GMS),0)*$Q14} -> 0 | W14: {=IFERROR(_xlfn.XLOOKUP($A14&W$4,MEN_DES&MEN_COD,MEN_GMS),0)*$Q14} -> 0 | X14: {=IFERROR(_xlfn.XLOOKUP($A14&X$4,MEN_DES&MEN_COD,MEN_GMS),0)*$Q14} -> 0 | Y14: {=IFERROR(_xlfn.XLOOKUP($A14&Y$4,MEN_DES&MEN_COD,MEN_GMS),0)*$Q14} -> 0 | ... AE14: {=IFERROR(_xlfn.XLOOKUP($A14&AE$4,MEN_DES&MEN_COD,MEN_GMS),0)*$Q14} -> 0 | AG14: {=IFERROR(_xlfn.XLOOKUP($A14&AG$4,MEN_DES&MEN_COD,MEN_GMS),0)*$Q14} -> 0 | AH14: {=IFERROR(_xlfn.XLOOKUP($A14&AH$4,MEN_DES&MEN_COD,MEN_GMS),0)*$Q14} -> 0 | AI14: {=IFERROR(_xlfn.XLOOKUP($A14&AI$4,MEN_DES&MEN_COD,MEN_GMS),0)*$Q14} -> 0 | AJ14: {=IFERROR(_xlfn.XLOOKUP($A14&AJ$4,MEN_DES&MEN_COD,MEN_GMS),0)*$Q14} -> 0 | AK14: {=IFERROR(_xlfn.XLOOKUP($A14&AK$4,MEN_DES&MEN_COD,MEN_GMS),0)*$Q14} -> 0 | AL14: {=IFERROR(_xlfn.XLOOKUP($A14&AL$4,MEN_DES&MEN_COD,MEN_GMS),0)*$Q14} -> 0 | AM14: {=IFERROR(_xlfn.XLOOKUP($A14&AM$4,MEN_DES&MEN_COD,MEN_GMS),0)*$Q14} -> 0 | AN14: {=IFERROR(_xlfn.XLOOKUP($A14&AN$4,MEN_DES&MEN_COD,MEN_GMS),0)*$Q14} -> 0 | ... BN14: {=IFERROR(_xlfn.XLOOKUP($A14&BN$4,MEN_DES&MEN_COD,MEN_GMS),0)*$Q14} -> 0 | BO14: =SUM(R14:BN14) -> 0
A15: [RM] Spicy Roast Pork Tomato Ramen | B15: 372.92 | C15: 1 | Q15: 1 | R15: {=IFERROR(_xlfn.XLOOKUP($A15&R$4,MEN_DES&MEN_COD,MEN_GMS),0)*$Q15} -> 0 | S15: {=IFERROR(_xlfn.XLOOKUP($A15&S$4,MEN_DES&MEN_COD,MEN_GMS),0)*$Q15} -> 0 | T15: {=IFERROR(_xlfn.XLOOKUP($A15&T$4,MEN_DES&MEN_COD,MEN_GMS),0)*$Q15} -> 0 | U15: {=IFERROR(_xlfn.XLOOKUP($A15&U$4,MEN_DES&MEN_COD,MEN_GMS),0)*$Q15} -> 0 | V15: {=IFERROR(_xlfn.XLOOKUP($A15&V$4,MEN_DES&MEN_COD,MEN_GMS),0)*$Q15} -> 0 | W15: {=IFERROR(_xlfn.XLOOKUP($A15&W$4,MEN_DES&MEN_COD,MEN_GMS),0)*$Q15} -> 0 | X15: {=IFERROR(_xlfn.XLOOKUP($A15&X$4,MEN_DES&MEN_COD,MEN_GMS),0)*$Q15} -> 0 | Y15: {=IFERROR(_xlfn.XLOOKUP($A15&Y$4,MEN_DES&MEN_COD,MEN_GMS),0)*$Q15} -> 1 | ... AE15: {=IFERROR(_xlfn.XLOOKUP($A15&AE$4,MEN_DES&MEN_COD,MEN_GMS),0)*$Q15} -> 0 | AG15: {=IFERROR(_xlfn.XLOOKUP($A15&AG$4,MEN_DES&MEN_COD,MEN_GMS),0)*$Q15} -> 0 | AH15: {=IFERROR(_xlfn.XLOOKUP($A15&AH$4,MEN_DES&MEN_COD,MEN_GMS),0)*$Q15} -> 0 | AI15: {=IFERROR(_xlfn.XLOOKUP($A15&AI$4,MEN_DES&MEN_COD,MEN_GMS),0)*$Q15} -> 0 | AJ15: {=IFERROR(_xlfn.XLOOKUP($A15&AJ$4,MEN_DES&MEN_COD,MEN_GMS),0)*$Q15} -> 0 | AK15: {=IFERROR(_xlfn.XLOOKUP($A15&AK$4,MEN_DES&MEN_COD,MEN_GMS),0)*$Q15} -> 0 | AL15: {=IFERROR(_xlfn.XLOOKUP($A15&AL$4,MEN_DES&MEN_COD,MEN_GMS),0)*$Q15} -> 0 | AM15: {=IFERROR(_xlfn.XLOOKUP($A15&AM$4,MEN_DES&MEN_COD,MEN_GMS),0)*$Q15} -> 0 | AN15: {=IFERROR(_xlfn.XLOOKUP($A15&AN$4,MEN_DES&MEN_COD,MEN_GMS),0)*$Q15} -> 0 | ... BN15: {=IFERROR(_xlfn.XLOOKUP($A15&BN$4,MEN_DES&MEN_COD,MEN_GMS),0)*$Q15} -> 0 | BO15: =SUM(R15:BN15) -> 48
A16: [RM] Tonkotsu Ramen | B16: 348.7 | C16: 1 | Q16: 1 | R16: {=IFERROR(_xlfn.XLOOKUP($A16&R$4,MEN_DES&MEN_COD,MEN_GMS),0)*$Q16} -> 0 | S16: {=IFERROR(_xlfn.XLOOKUP($A16&S$4,MEN_DES&MEN_COD,MEN_GMS),0)*$Q16} -> 0 | T16: {=IFERROR(_xlfn.XLOOKUP($A16&T$4,MEN_DES&MEN_COD,MEN_GMS),0)*$Q16} -> 0 | U16: {=IFERROR(_xlfn.XLOOKUP($A16&U$4,MEN_DES&MEN_COD,MEN_GMS),0)*$Q16} -> 0 | V16: {=IFERROR(_xlfn.XLOOKUP($A16&V$4,MEN_DES&MEN_COD,MEN_GMS),0)*$Q16} -> 0 | W16: {=IFERROR(_xlfn.XLOOKUP($A16&W$4,MEN_DES&MEN_COD,MEN_GMS),0)*$Q16} -> 0 | X16: {=IFERROR(_xlfn.XLOOKUP($A16&X$4,MEN_DES&MEN_COD,MEN_GMS),0)*$Q16} -> 0 | Y16: {=IFERROR(_xlfn.XLOOKUP($A16&Y$4,MEN_DES&MEN_COD,MEN_GMS),0)*$Q16} -> 1 | ... AE16: {=IFERROR(_xlfn.XLOOKUP($A16&AE$4,MEN_DES&MEN_COD,MEN_GMS),0)*$Q16} -> 0 | AG16: {=IFERROR(_xlfn.XLOOKUP($A16&AG$4,MEN_DES&MEN_COD,MEN_GMS),0)*$Q16} -> 0 | AH16: {=IFERROR(_xlfn.XLOOKUP($A16&AH$4,MEN_DES&MEN_COD,MEN_GMS),0)*$Q16} -> 0 | AI16: {=IFERROR(_xlfn.XLOOKUP($A16&AI$4,MEN_DES&MEN_COD,MEN_GMS),0)*$Q16} -> 0 | AJ16: {=IFERROR(_xlfn.XLOOKUP($A16&AJ$4,MEN_DES&MEN_COD,MEN_GMS),0)*$Q16} -> 0 | AK16: {=IFERROR(_xlfn.XLOOKUP($A16&AK$4,MEN_DES&MEN_COD,MEN_GMS),0)*$Q16} -> 0 | AL16: {=IFERROR(_xlfn.XLOOKUP($A16&AL$4,MEN_DES&MEN_COD,MEN_GMS),0)*$Q16} -> 0 | AM16: {=IFERROR(_xlfn.XLOOKUP($A16&AM$4,MEN_DES&MEN_COD,MEN_GMS),0)*$Q16} -> 0 | AN16: {=IFERROR(_xlfn.XLOOKUP($A16&AN$4,MEN_DES&MEN_COD,MEN_GMS),0)*$Q16} -> 0 | ... BN16: {=IFERROR(_xlfn.XLOOKUP($A16&BN$4,MEN_DES&MEN_COD,MEN_GMS),0)*$Q16} -> 0 | BO16: =SUM(R16:BN16) -> 48
A17: [SB] Cheesy Beef Terriyaki Burrito | B17: 690 | C17: 2 | Q17: 2 | R17: {=IFERROR(_xlfn.XLOOKUP($A17&R$4,MEN_DES&MEN_COD,MEN_GMS),0)*$Q17} -> 2 | S17: {=IFERROR(_xlfn.XLOOKUP($A17&S$4,MEN_DES&MEN_COD,MEN_GMS),0)*$Q17} -> 0 | T17: {=IFERROR(_xlfn.XLOOKUP($A17&T$4,MEN_DES&MEN_COD,MEN_GMS),0)*$Q17} -> 0 | U17: {=IFERROR(_xlfn.XLOOKUP($A17&U$4,MEN_DES&MEN_COD,MEN_GMS),0)*$Q17} -> 0 | V17: {=IFERROR(_xlfn.XLOOKUP($A17&V$4,MEN_DES&MEN_COD,MEN_GMS),0)*$Q17} -> 0 | W17: {=IFERROR(_xlfn.XLOOKUP($A17&W$4,MEN_DES&MEN_COD,MEN_GMS),0)*$Q17} -> 0 | X17: {=IFERROR(_xlfn.XLOOKUP($A17&X$4,MEN_DES&MEN_COD,MEN_GMS),0)*$Q17} -> 0 | Y17: {=IFERROR(_xlfn.XLOOKUP($A17&Y$4,MEN_DES&MEN_COD,MEN_GMS),0)*$Q17} -> 0 | ... AE17: {=IFERROR(_xlfn.XLOOKUP($A17&AE$4,MEN_DES&MEN_COD,MEN_GMS),0)*$Q17} -> 0 | AG17: {=IFERROR(_xlfn.XLOOKUP($A17&AG$4,MEN_DES&MEN_COD,MEN_GMS),0)*$Q17} -> 0 | AH17: {=IFERROR(_xlfn.XLOOKUP($A17&AH$4,MEN_DES&MEN_COD,MEN_GMS),0)*$Q17} -> 0 | AI17: {=IFERROR(_xlfn.XLOOKUP($A17&AI$4,MEN_DES&MEN_COD,MEN_GMS),0)*$Q17} -> 0 | AJ17: {=IFERROR(_xlfn.XLOOKUP($A17&AJ$4,MEN_DES&MEN_COD,MEN_GMS),0)*$Q17} -> 0 | AK17: {=IFERROR(_xlfn.XLOOKUP($A17&AK$4,MEN_DES&MEN_COD,MEN_GMS),0)*$Q17} -> 0 | AL17: {=IFERROR(_xlfn.XLOOKUP($A17&AL$4,MEN_DES&MEN_COD,MEN_GMS),0)*$Q17} -> 0 | AM17: {=IFERROR(_xlfn.XLOOKUP($A17&AM$4,MEN_DES&MEN_COD,MEN_GMS),0)*$Q17} -> 0 | AN17: {=IFERROR(_xlfn.XLOOKUP($A17&AN$4,MEN_DES&MEN_COD,MEN_GMS),0)*$Q17} -> 0 | ... BN17: {=IFERROR(_xlfn.XLOOKUP($A17&BN$4,MEN_DES&MEN_COD,MEN_GMS),0)*$Q17} -> 0 | BO17: =SUM(R17:BN17) -> 2
A18: [ST] Okonomiyaki Cheesy Beef (Regular) | B18: 320 | C18: 1 | Q18: 1 | R18: {=IFERROR(_xlfn.XLOOKUP($A18&R$4,MEN_DES&MEN_COD,MEN_GMS),0)*$Q18} -> 0 | S18: {=IFERROR(_xlfn.XLOOKUP($A18&S$4,MEN_DES&MEN_COD,MEN_GMS),0)*$Q18} -> 0 | T18: {=IFERROR(_xlfn.XLOOKUP($A18&T$4,MEN_DES&MEN_COD,MEN_GMS),0)*$Q18} -> 0 | U18: {=IFERROR(_xlfn.XLOOKUP($A18&U$4,MEN_DES&MEN_COD,MEN_GMS),0)*$Q18} -> 0 | V18: {=IFERROR(_xlfn.XLOOKUP($A18&V$4,MEN_DES&MEN_COD,MEN_GMS),0)*$Q18} -> 0 | W18: {=IFERROR(_xlfn.XLOOKUP($A18&W$4,MEN_DES&MEN_COD,MEN_GMS),0)*$Q18} -> 0 | X18: {=IFERROR(_xlfn.XLOOKUP($A18&X$4,MEN_DES&MEN_COD,MEN_GMS),0)*$Q18} -> 0 | Y18: {=IFERROR(_xlfn.XLOOKUP($A18&Y$4,MEN_DES&MEN_COD,MEN_GMS),0)*$Q18} -> 0 | ... AE18: {=IFERROR(_xlfn.XLOOKUP($A18&AE$4,MEN_DES&MEN_COD,MEN_GMS),0)*$Q18} -> 0 | AG18: {=IFERROR(_xlfn.XLOOKUP($A18&AG$4,MEN_DES&MEN_COD,MEN_GMS),0)*$Q18} -> 0 | AH18: {=IFERROR(_xlfn.XLOOKUP($A18&AH$4,MEN_DES&MEN_COD,MEN_GMS),0)*$Q18} -> 0 | AI18: {=IFERROR(_xlfn.XLOOKUP($A18&AI$4,MEN_DES&MEN_COD,MEN_GMS),0)*$Q18} -> 0 | AJ18: {=IFERROR(_xlfn.XLOOKUP($A18&AJ$4,MEN_DES&MEN_COD,MEN_GMS),0)*$Q18} -> 0 | AK18: {=IFERROR(_xlfn.XLOOKUP($A18&AK$4,MEN_DES&MEN_COD,MEN_GMS),0)*$Q18} -> 0 | AL18: {=IFERROR(_xlfn.XLOOKUP($A18&AL$4,MEN_DES&MEN_COD,MEN_GMS),0)*$Q18} -> 0 | AM18: {=IFERROR(_xlfn.XLOOKUP($A18&AM$4,MEN_DES&MEN_COD,MEN_GMS),0)*$Q18} -> 0 | AN18: {=IFERROR(_xlfn.XLOOKUP($A18&AN$4,MEN_DES&MEN_COD,MEN_GMS),0)*$Q18} -> 0 | ... BN18: {=IFERROR(_xlfn.XLOOKUP($A18&BN$4,MEN_DES&MEN_COD,MEN_GMS),0)*$Q18} -> 0 | BO18: =SUM(R18:BN18) -> 0
A19: Shoyu Seafood Ramen | B19: 289 | C19: 1 | Q19: 1 | R19: {=IFERROR(_xlfn.XLOOKUP($A19&R$4,MEN_DES&MEN_COD,MEN_GMS),0)*$Q19} -> 0 | S19: {=IFERROR(_xlfn.XLOOKUP($A19&S$4,MEN_DES&MEN_COD,MEN_GMS),0)*$Q19} -> 0 | T19: {=IFERROR(_xlfn.XLOOKUP($A19&T$4,MEN_DES&MEN_COD,MEN_GMS),0)*$Q19} -> 0 | U19: {=IFERROR(_xlfn.XLOOKUP($A19&U$4,MEN_DES&MEN_COD,MEN_GMS),0)*$Q19} -> 0 | V19: {=IFERROR(_xlfn.XLOOKUP($A19&V$4,MEN_DES&MEN_COD,MEN_GMS),0)*$Q19} -> 0 | W19: {=IFERROR(_xlfn.XLOOKUP($A19&W$4,MEN_DES&MEN_COD,MEN_GMS),0)*$Q19} -> 0 | X19: {=IFERROR(_xlfn.XLOOKUP($A19&X$4,MEN_DES&MEN_COD,MEN_GMS),0)*$Q19} -> 0 | Y19: {=IFERROR(_xlfn.XLOOKUP($A19&Y$4,MEN_DES&MEN_COD,MEN_GMS),0)*$Q19} -> 0 | ... AE19: {=IFERROR(_xlfn.XLOOKUP($A19&AE$4,MEN_DES&MEN_COD,MEN_GMS),0)*$Q19} -> 0 | AG19: {=IFERROR(_xlfn.XLOOKUP($A19&AG$4,MEN_DES&MEN_COD,MEN_GMS),0)*$Q19} -> 30 | AH19: {=IFERROR(_xlfn.XLOOKUP($A19&AH$4,MEN_DES&MEN_COD,MEN_GMS),0)*$Q19} -> 0 | AI19: {=IFERROR(_xlfn.XLOOKUP($A19&AI$4,MEN_DES&MEN_COD,MEN_GMS),0)*$Q19} -> 20 | AJ19: {=IFERROR(_xlfn.XLOOKUP($A19&AJ$4,MEN_DES&MEN_COD,MEN_GMS),0)*$Q19} -> 0 | AK19: {=IFERROR(_xlfn.XLOOKUP($A19&AK$4,MEN_DES&MEN_COD,MEN_GMS),0)*$Q19} -> 0 | AL19: {=IFERROR(_xlfn.XLOOKUP($A19&AL$4,MEN_DES&MEN_COD,MEN_GMS),0)*$Q19} -> 0 | AM19: {=IFERROR(_xlfn.XLOOKUP($A19&AM$4,MEN_DES&MEN_COD,MEN_GMS),0)*$Q19} -> 0 | AN19: {=IFERROR(_xlfn.XLOOKUP($A19&AN$4,MEN_DES&MEN_COD,MEN_GMS),0)*$Q19} -> 0 | ... BN19: {=IFERROR(_xlfn.XLOOKUP($A19&BN$4,MEN_DES&MEN_COD,MEN_GMS),0)*$Q19} -> 0 | BO19: =SUM(R19:BN19) -> 99
A20: Grand Total | B20: 4323 | C20: 17 | Q20: 17 | R20: {=IFERROR(_xlfn.XLOOKUP($A20&R$4,MEN_DES&MEN_COD,MEN_GMS),0)*$Q20} -> 0 | S20: {=IFERROR(_xlfn.XLOOKUP($A20&S$4,MEN_DES&MEN_COD,MEN_GMS),0)*$Q20} -> 0 | T20: {=IFERROR(_xlfn.XLOOKUP($A20&T$4,MEN_DES&MEN_COD,MEN_GMS),0)*$Q20} -> 0 | U20: {=IFERROR(_xlfn.XLOOKUP($A20&U$4,MEN_DES&MEN_COD,MEN_GMS),0)*$Q20} -> 0 | V20: {=IFERROR(_xlfn.XLOOKUP($A20&V$4,MEN_DES&MEN_COD,MEN_GMS),0)*$Q20} -> 0 | W20: {=IFERROR(_xlfn.XLOOKUP($A20&W$4,MEN_DES&MEN_COD,MEN_GMS),0)*$Q20} -> 0 | X20: {=IFERROR(_xlfn.XLOOKUP($A20&X$4,MEN_DES&MEN_COD,MEN_GMS),0)*$Q20} -> 0 | Y20: {=IFERROR(_xlfn.XLOOKUP($A20&Y$4,MEN_DES&MEN_COD,MEN_GMS),0)*$Q20} -> 0 | ... AE20: {=IFERROR(_xlfn.XLOOKUP($A20&AE$4,MEN_DES&MEN_COD,MEN_GMS),0)*$Q20} -> 0 | AG20: {=IFERROR(_xlfn.XLOOKUP($A20&AG$4,MEN_DES&MEN_COD,MEN_GMS),0)*$Q20} -> 0 | AH20: {=IFERROR(_xlfn.XLOOKUP($A20&AH$4,MEN_DES&MEN_COD,MEN_GMS),0)*$Q20} -> 0 | AI20: {=IFERROR(_xlfn.XLOOKUP($A20&AI$4,MEN_DES&MEN_COD,MEN_GMS),0)*$Q20} -> 0 | AJ20: {=IFERROR(_xlfn.XLOOKUP($A20&AJ$4,MEN_DES&MEN_COD,MEN_GMS),0)*$Q20} -> 0 | AK20: {=IFERROR(_xlfn.XLOOKUP($A20&AK$4,MEN_DES&MEN_COD,MEN_GMS),0)*$Q20} -> 0 | AL20: {=IFERROR(_xlfn.XLOOKUP($A20&AL$4,MEN_DES&MEN_COD,MEN_GMS),0)*$Q20} -> 0 | AM20: {=IFERROR(_xlfn.XLOOKUP($A20&AM$4,MEN_DES&MEN_COD,MEN_GMS),0)*$Q20} -> 0 | AN20: {=IFERROR(_xlfn.XLOOKUP($A20&AN$4,MEN_DES&MEN_COD,MEN_GMS),0)*$Q20} -> 0 | ... BN20: {=IFERROR(_xlfn.XLOOKUP($A20&BN$4,MEN_DES&MEN_COD,MEN_GMS),0)*$Q20} -> 0 | BO20: =SUM(R20:BN20) -> 0
R21: {=IFERROR(_xlfn.XLOOKUP($A21&R$4,MEN_DES&MEN_COD,MEN_GMS),0)*$Q21} -> 0 | S21: {=IFERROR(_xlfn.XLOOKUP($A21&S$4,MEN_DES&MEN_COD,MEN_GMS),0)*$Q21} -> 0 | T21: {=IFERROR(_xlfn.XLOOKUP($A21&T$4,MEN_DES&MEN_COD,MEN_GMS),0)*$Q21} -> 0 | U21: {=IFERROR(_xlfn.XLOOKUP($A21&U$4,MEN_DES&MEN_COD,MEN_GMS),0)*$Q21} -> 0 | V21: {=IFERROR(_xlfn.XLOOKUP($A21&V$4,MEN_DES&MEN_COD,MEN_GMS),0)*$Q21} -> 0 | W21: {=IFERROR(_xlfn.XLOOKUP($A21&W$4,MEN_DES&MEN_COD,MEN_GMS),0)*$Q21} -> 0 | X21: {=IFERROR(_xlfn.XLOOKUP($A21&X$4,MEN_DES&MEN_COD,MEN_GMS),0)*$Q21} -> 0 | Y21: {=IFERROR(_xlfn.XLOOKUP($A21&Y$4,MEN_DES&MEN_COD,MEN_GMS),0)*$Q21} -> 0 | ... AE21: {=IFERROR(_xlfn.XLOOKUP($A21&AE$4,MEN_DES&MEN_COD,MEN_GMS),0)*$Q21} -> 0 | AG21: {=IFERROR(_xlfn.XLOOKUP($A21&AG$4,MEN_DES&MEN_COD,MEN_GMS),0)*$Q21} -> 0 | AH21: {=IFERROR(_xlfn.XLOOKUP($A21&AH$4,MEN_DES&MEN_COD,MEN_GMS),0)*$Q21} -> 0 | AI21: {=IFERROR(_xlfn.XLOOKUP($A21&AI$4,MEN_DES&MEN_COD,MEN_GMS),0)*$Q21} -> 0 | AJ21: {=IFERROR(_xlfn.XLOOKUP($A21&AJ$4,MEN_DES&MEN_COD,MEN_GMS),0)*$Q21} -> 0 | AK21: {=IFERROR(_xlfn.XLOOKUP($A21&AK$4,MEN_DES&MEN_COD,MEN_GMS),0)*$Q21} -> 0 | AL21: {=IFERROR(_xlfn.XLOOKUP($A21&AL$4,MEN_DES&MEN_COD,MEN_GMS),0)*$Q21} -> 0 | AM21: {=IFERROR(_xlfn.XLOOKUP($A21&AM$4,MEN_DES&MEN_COD,MEN_GMS),0)*$Q21} -> 0 | AN21: {=IFERROR(_xlfn.XLOOKUP($A21&AN$4,MEN_DES&MEN_COD,MEN_GMS),0)*$Q21} -> 0 | ... BN21: {=IFERROR(_xlfn.XLOOKUP($A21&BN$4,MEN_DES&MEN_COD,MEN_GMS),0)*$Q21} -> 0 | BO21: =SUM(R21:BN21) -> 0
R22: {=IFERROR(_xlfn.XLOOKUP($A22&R$4,MEN_DES&MEN_COD,MEN_GMS),0)*$Q22} -> 0 | S22: {=IFERROR(_xlfn.XLOOKUP($A22&S$4,MEN_DES&MEN_COD,MEN_GMS),0)*$Q22} -> 0 | T22: {=IFERROR(_xlfn.XLOOKUP($A22&T$4,MEN_DES&MEN_COD,MEN_GMS),0)*$Q22} -> 0 | U22: {=IFERROR(_xlfn.XLOOKUP($A22&U$4,MEN_DES&MEN_COD,MEN_GMS),0)*$Q22} -> 0 | V22: {=IFERROR(_xlfn.XLOOKUP($A22&V$4,MEN_DES&MEN_COD,MEN_GMS),0)*$Q22} -> 0 | W22: {=IFERROR(_xlfn.XLOOKUP($A22&W$4,MEN_DES&MEN_COD,MEN_GMS),0)*$Q22} -> 0 | X22: {=IFERROR(_xlfn.XLOOKUP($A22&X$4,MEN_DES&MEN_COD,MEN_GMS),0)*$Q22} -> 0 | Y22: {=IFERROR(_xlfn.XLOOKUP($A22&Y$4,MEN_DES&MEN_COD,MEN_GMS),0)*$Q22} -> 0 | ... AE22: {=IFERROR(_xlfn.XLOOKUP($A22&AE$4,MEN_DES&MEN_COD,MEN_GMS),0)*$Q22} -> 0 | AG22: {=IFERROR(_xlfn.XLOOKUP($A22&AG$4,MEN_DES&MEN_COD,MEN_GMS),0)*$Q22} -> 0 | AH22: {=IFERROR(_xlfn.XLOOKUP($A22&AH$4,MEN_DES&MEN_COD,MEN_GMS),0)*$Q22} -> 0 | AI22: {=IFERROR(_xlfn.XLOOKUP($A22&AI$4,MEN_DES&MEN_COD,MEN_GMS),0)*$Q22} -> 0 | AJ22: {=IFERROR(_xlfn.XLOOKUP($A22&AJ$4,MEN_DES&MEN_COD,MEN_GMS),0)*$Q22} -> 0 | AK22: {=IFERROR(_xlfn.XLOOKUP($A22&AK$4,MEN_DES&MEN_COD,MEN_GMS),0)*$Q22} -> 0 | AL22: {=IFERROR(_xlfn.XLOOKUP($A22&AL$4,MEN_DES&MEN_COD,MEN_GMS),0)*$Q22} -> 0 | AM22: {=IFERROR(_xlfn.XLOOKUP($A22&AM$4,MEN_DES&MEN_COD,MEN_GMS),0)*$Q22} -> 0 | AN22: {=IFERROR(_xlfn.XLOOKUP($A22&AN$4,MEN_DES&MEN_COD,MEN_GMS),0)*$Q22} -> 0 | ... BN22: {=IFERROR(_xlfn.XLOOKUP($A22&BN$4,MEN_DES&MEN_COD,MEN_GMS),0)*$Q22} -> 0 | BO22: =SUM(R22:BN22) -> 0
R23: {=IFERROR(_xlfn.XLOOKUP($A23&R$4,MEN_DES&MEN_COD,MEN_GMS),0)*$Q23} -> 0 | S23: {=IFERROR(_xlfn.XLOOKUP($A23&S$4,MEN_DES&MEN_COD,MEN_GMS),0)*$Q23} -> 0 | T23: {=IFERROR(_xlfn.XLOOKUP($A23&T$4,MEN_DES&MEN_COD,MEN_GMS),0)*$Q23} -> 0 | U23: {=IFERROR(_xlfn.XLOOKUP($A23&U$4,MEN_DES&MEN_COD,MEN_GMS),0)*$Q23} -> 0 | V23: {=IFERROR(_xlfn.XLOOKUP($A23&V$4,MEN_DES&MEN_COD,MEN_GMS),0)*$Q23} -> 0 | W23: {=IFERROR(_xlfn.XLOOKUP($A23&W$4,MEN_DES&MEN_COD,MEN_GMS),0)*$Q23} -> 0 | X23: {=IFERROR(_xlfn.XLOOKUP($A23&X$4,MEN_DES&MEN_COD,MEN_GMS),0)*$Q23} -> 0 | Y23: {=IFERROR(_xlfn.XLOOKUP($A23&Y$4,MEN_DES&MEN_COD,MEN_GMS),0)*$Q23} -> 0 | ... AE23: {=IFERROR(_xlfn.XLOOKUP($A23&AE$4,MEN_DES&MEN_COD,MEN_GMS),0)*$Q23} -> 0 | AG23: {=IFERROR(_xlfn.XLOOKUP($A23&AG$4,MEN_DES&MEN_COD,MEN_GMS),0)*$Q23} -> 0 | AH23: {=IFERROR(_xlfn.XLOOKUP($A23&AH$4,MEN_DES&MEN_COD,MEN_GMS),0)*$Q23} -> 0 | AI23: {=IFERROR(_xlfn.XLOOKUP($A23&AI$4,MEN_DES&MEN_COD,MEN_GMS),0)*$Q23} -> 0 | AJ23: {=IFERROR(_xlfn.XLOOKUP($A23&AJ$4,MEN_DES&MEN_COD,MEN_GMS),0)*$Q23} -> 0 | AK23: {=IFERROR(_xlfn.XLOOKUP($A23&AK$4,MEN_DES&MEN_COD,MEN_GMS),0)*$Q23} -> 0 | AL23: {=IFERROR(_xlfn.XLOOKUP($A23&AL$4,MEN_DES&MEN_COD,MEN_GMS),0)*$Q23} -> 0 | AM23: {=IFERROR(_xlfn.XLOOKUP($A23&AM$4,MEN_DES&MEN_COD,MEN_GMS),0)*$Q23} -> 0 | AN23: {=IFERROR(_xlfn.XLOOKUP($A23&AN$4,MEN_DES&MEN_COD,MEN_GMS),0)*$Q23} -> 0 | ... BN23: {=IFERROR(_xlfn.XLOOKUP($A23&BN$4,MEN_DES&MEN_COD,MEN_GMS),0)*$Q23} -> 0 | BO23: =SUM(R23:BN23) -> 0
R24: {=IFERROR(_xlfn.XLOOKUP($A24&R$4,MEN_DES&MEN_COD,MEN_GMS),0)*$Q24} -> 0 | S24: {=IFERROR(_xlfn.XLOOKUP($A24&S$4,MEN_DES&MEN_COD,MEN_GMS),0)*$Q24} -> 0 | T24: {=IFERROR(_xlfn.XLOOKUP($A24&T$4,MEN_DES&MEN_COD,MEN_GMS),0)*$Q24} -> 0 | U24: {=IFERROR(_xlfn.XLOOKUP($A24&U$4,MEN_DES&MEN_COD,MEN_GMS),0)*$Q24} -> 0 | V24: {=IFERROR(_xlfn.XLOOKUP($A24&V$4,MEN_DES&MEN_COD,MEN_GMS),0)*$Q24} -> 0 | W24: {=IFERROR(_xlfn.XLOOKUP($A24&W$4,MEN_DES&MEN_COD,MEN_GMS),0)*$Q24} -> 0 | X24: {=IFERROR(_xlfn.XLOOKUP($A24&X$4,MEN_DES&MEN_COD,MEN_GMS),0)*$Q24} -> 0 | Y24: {=IFERROR(_xlfn.XLOOKUP($A24&Y$4,MEN_DES&MEN_COD,MEN_GMS),0)*$Q24} -> 0 | ... AE24: {=IFERROR(_xlfn.XLOOKUP($A24&AE$4,MEN_DES&MEN_COD,MEN_GMS),0)*$Q24} -> 0 | AG24: {=IFERROR(_xlfn.XLOOKUP($A24&AG$4,MEN_DES&MEN_COD,MEN_GMS),0)*$Q24} -> 0 | AH24: {=IFERROR(_xlfn.XLOOKUP($A24&AH$4,MEN_DES&MEN_COD,MEN_GMS),0)*$Q24} -> 0 | AI24: {=IFERROR(_xlfn.XLOOKUP($A24&AI$4,MEN_DES&MEN_COD,MEN_GMS),0)*$Q24} -> 0 | AJ24: {=IFERROR(_xlfn.XLOOKUP($A24&AJ$4,MEN_DES&MEN_COD,MEN_GMS),0)*$Q24} -> 0 | AK24: {=IFERROR(_xlfn.XLOOKUP($A24&AK$4,MEN_DES&MEN_COD,MEN_GMS),0)*$Q24} -> 0 | AL24: {=IFERROR(_xlfn.XLOOKUP($A24&AL$4,MEN_DES&MEN_COD,MEN_GMS),0)*$Q24} -> 0 | AM24: {=IFERROR(_xlfn.XLOOKUP($A24&AM$4,MEN_DES&MEN_COD,MEN_GMS),0)*$Q24} -> 0 | AN24: {=IFERROR(_xlfn.XLOOKUP($A24&AN$4,MEN_DES&MEN_COD,MEN_GMS),0)*$Q24} -> 0 | ... BN24: {=IFERROR(_xlfn.XLOOKUP($A24&BN$4,MEN_DES&MEN_COD,MEN_GMS),0)*$Q24} -> 0 | BO24: =SUM(R24:BN24) -> 0
R25: {=IFERROR(_xlfn.XLOOKUP($A25&R$4,MEN_DES&MEN_COD,MEN_GMS),0)*$Q25} -> 0 | S25: {=IFERROR(_xlfn.XLOOKUP($A25&S$4,MEN_DES&MEN_COD,MEN_GMS),0)*$Q25} -> 0 | T25: {=IFERROR(_xlfn.XLOOKUP($A25&T$4,MEN_DES&MEN_COD,MEN_GMS),0)*$Q25} -> 0 | U25: {=IFERROR(_xlfn.XLOOKUP($A25&U$4,MEN_DES&MEN_COD,MEN_GMS),0)*$Q25} -> 0 | V25: {=IFERROR(_xlfn.XLOOKUP($A25&V$4,MEN_DES&MEN_COD,MEN_GMS),0)*$Q25} -> 0 | W25: {=IFERROR(_xlfn.XLOOKUP($A25&W$4,MEN_DES&MEN_COD,MEN_GMS),0)*$Q25} -> 0 | X25: {=IFERROR(_xlfn.XLOOKUP($A25&X$4,MEN_DES&MEN_COD,MEN_GMS),0)*$Q25} -> 0 | Y25: {=IFERROR(_xlfn.XLOOKUP($A25&Y$4,MEN_DES&MEN_COD,MEN_GMS),0)*$Q25} -> 0 | ... AE25: {=IFERROR(_xlfn.XLOOKUP($A25&AE$4,MEN_DES&MEN_COD,MEN_GMS),0)*$Q25} -> 0 | AG25: {=IFERROR(_xlfn.XLOOKUP($A25&AG$4,MEN_DES&MEN_COD,MEN_GMS),0)*$Q25} -> 0 | AH25: {=IFERROR(_xlfn.XLOOKUP($A25&AH$4,MEN_DES&MEN_COD,MEN_GMS),0)*$Q25} -> 0 | AI25: {=IFERROR(_xlfn.XLOOKUP($A25&AI$4,MEN_DES&MEN_COD,MEN_GMS),0)*$Q25} -> 0 | AJ25: {=IFERROR(_xlfn.XLOOKUP($A25&AJ$4,MEN_DES&MEN_COD,MEN_GMS),0)*$Q25} -> 0 | AK25: {=IFERROR(_xlfn.XLOOKUP($A25&AK$4,MEN_DES&MEN_COD,MEN_GMS),0)*$Q25} -> 0 | AL25: {=IFERROR(_xlfn.XLOOKUP($A25&AL$4,MEN_DES&MEN_COD,MEN_GMS),0)*$Q25} -> 0 | AM25: {=IFERROR(_xlfn.XLOOKUP($A25&AM$4,MEN_DES&MEN_COD,MEN_GMS),0)*$Q25} -> 0 | AN25: {=IFERROR(_xlfn.XLOOKUP($A25&AN$4,MEN_DES&MEN_COD,MEN_GMS),0)*$Q25} -> 0 | ... BN25: {=IFERROR(_xlfn.XLOOKUP($A25&BN$4,MEN_DES&MEN_COD,MEN_GMS),0)*$Q25} -> 0 | BO25: =SUM(R25:BN25) -> 0
R26: {=IFERROR(_xlfn.XLOOKUP($A26&R$4,MEN_DES&MEN_COD,MEN_GMS),0)*$Q26} -> 0 | S26: {=IFERROR(_xlfn.XLOOKUP($A26&S$4,MEN_DES&MEN_COD,MEN_GMS),0)*$Q26} -> 0 | T26: {=IFERROR(_xlfn.XLOOKUP($A26&T$4,MEN_DES&MEN_COD,MEN_GMS),0)*$Q26} -> 0 | U26: {=IFERROR(_xlfn.XLOOKUP($A26&U$4,MEN_DES&MEN_COD,MEN_GMS),0)*$Q26} -> 0 | V26: {=IFERROR(_xlfn.XLOOKUP($A26&V$4,MEN_DES&MEN_COD,MEN_GMS),0)*$Q26} -> 0 | W26: {=IFERROR(_xlfn.XLOOKUP($A26&W$4,MEN_DES&MEN_COD,MEN_GMS),0)*$Q26} -> 0 | X26: {=IFERROR(_xlfn.XLOOKUP($A26&X$4,MEN_DES&MEN_COD,MEN_GMS),0)*$Q26} -> 0 | Y26: {=IFERROR(_xlfn.XLOOKUP($A26&Y$4,MEN_DES&MEN_COD,MEN_GMS),0)*$Q26} -> 0 | ... AE26: {=IFERROR(_xlfn.XLOOKUP($A26&AE$4,MEN_DES&MEN_COD,MEN_GMS),0)*$Q26} -> 0 | AG26: {=IFERROR(_xlfn.XLOOKUP($A26&AG$4,MEN_DES&MEN_COD,MEN_GMS),0)*$Q26} -> 0 | AH26: {=IFERROR(_xlfn.XLOOKUP($A26&AH$4,MEN_DES&MEN_COD,MEN_GMS),0)*$Q26} -> 0 | AI26: {=IFERROR(_xlfn.XLOOKUP($A26&AI$4,MEN_DES&MEN_COD,MEN_GMS),0)*$Q26} -> 0 | AJ26: {=IFERROR(_xlfn.XLOOKUP($A26&AJ$4,MEN_DES&MEN_COD,MEN_GMS),0)*$Q26} -> 0 | AK26: {=IFERROR(_xlfn.XLOOKUP($A26&AK$4,MEN_DES&MEN_COD,MEN_GMS),0)*$Q26} -> 0 | AL26: {=IFERROR(_xlfn.XLOOKUP($A26&AL$4,MEN_DES&MEN_COD,MEN_GMS),0)*$Q26} -> 0 | AM26: {=IFERROR(_xlfn.XLOOKUP($A26&AM$4,MEN_DES&MEN_COD,MEN_GMS),0)*$Q26} -> 0 | AN26: {=IFERROR(_xlfn.XLOOKUP($A26&AN$4,MEN_DES&MEN_COD,MEN_GMS),0)*$Q26} -> 0 | ... BN26: {=IFERROR(_xlfn.XLOOKUP($A26&BN$4,MEN_DES&MEN_COD,MEN_GMS),0)*$Q26} -> 0 | BO26: =SUM(R26:BN26) -> 0
R27: {=IFERROR(_xlfn.XLOOKUP($A27&R$4,MEN_DES&MEN_COD,MEN_GMS),0)*$Q27} -> 0 | S27: {=IFERROR(_xlfn.XLOOKUP($A27&S$4,MEN_DES&MEN_COD,MEN_GMS),0)*$Q27} -> 0 | T27: {=IFERROR(_xlfn.XLOOKUP($A27&T$4,MEN_DES&MEN_COD,MEN_GMS),0)*$Q27} -> 0 | U27: {=IFERROR(_xlfn.XLOOKUP($A27&U$4,MEN_DES&MEN_COD,MEN_GMS),0)*$Q27} -> 0 | V27: {=IFERROR(_xlfn.XLOOKUP($A27&V$4,MEN_DES&MEN_COD,MEN_GMS),0)*$Q27} -> 0 | W27: {=IFERROR(_xlfn.XLOOKUP($A27&W$4,MEN_DES&MEN_COD,MEN_GMS),0)*$Q27} -> 0 | X27: {=IFERROR(_xlfn.XLOOKUP($A27&X$4,MEN_DES&MEN_COD,MEN_GMS),0)*$Q27} -> 0 | Y27: {=IFERROR(_xlfn.XLOOKUP($A27&Y$4,MEN_DES&MEN_COD,MEN_GMS),0)*$Q27} -> 0 | ... AE27: {=IFERROR(_xlfn.XLOOKUP($A27&AE$4,MEN_DES&MEN_COD,MEN_GMS),0)*$Q27} -> 0 | AG27: {=IFERROR(_xlfn.XLOOKUP($A27&AG$4,MEN_DES&MEN_COD,MEN_GMS),0)*$Q27} -> 0 | AH27: {=IFERROR(_xlfn.XLOOKUP($A27&AH$4,MEN_DES&MEN_COD,MEN_GMS),0)*$Q27} -> 0 | AI27: {=IFERROR(_xlfn.XLOOKUP($A27&AI$4,MEN_DES&MEN_COD,MEN_GMS),0)*$Q27} -> 0 | AJ27: {=IFERROR(_xlfn.XLOOKUP($A27&AJ$4,MEN_DES&MEN_COD,MEN_GMS),0)*$Q27} -> 0 | AK27: {=IFERROR(_xlfn.XLOOKUP($A27&AK$4,MEN_DES&MEN_COD,MEN_GMS),0)*$Q27} -> 0 | AL27: {=IFERROR(_xlfn.XLOOKUP($A27&AL$4,MEN_DES&MEN_COD,MEN_GMS),0)*$Q27} -> 0 | AM27: {=IFERROR(_xlfn.XLOOKUP($A27&AM$4,MEN_DES&MEN_COD,MEN_GMS),0)*$Q27} -> 0 | AN27: {=IFERROR(_xlfn.XLOOKUP($A27&AN$4,MEN_DES&MEN_COD,MEN_GMS),0)*$Q27} -> 0 | ... BN27: {=IFERROR(_xlfn.XLOOKUP($A27&BN$4,MEN_DES&MEN_COD,MEN_GMS),0)*$Q27} -> 0 | BO27: =SUM(R27:BN27) -> 0
R28: {=IFERROR(_xlfn.XLOOKUP($A28&R$4,MEN_DES&MEN_COD,MEN_GMS),0)*$Q28} -> 0 | S28: {=IFERROR(_xlfn.XLOOKUP($A28&S$4,MEN_DES&MEN_COD,MEN_GMS),0)*$Q28} -> 0 | T28: {=IFERROR(_xlfn.XLOOKUP($A28&T$4,MEN_DES&MEN_COD,MEN_GMS),0)*$Q28} -> 0 | U28: {=IFERROR(_xlfn.XLOOKUP($A28&U$4,MEN_DES&MEN_COD,MEN_GMS),0)*$Q28} -> 0 | V28: {=IFERROR(_xlfn.XLOOKUP($A28&V$4,MEN_DES&MEN_COD,MEN_GMS),0)*$Q28} -> 0 | W28: {=IFERROR(_xlfn.XLOOKUP($A28&W$4,MEN_DES&MEN_COD,MEN_GMS),0)*$Q28} -> 0 | X28: {=IFERROR(_xlfn.XLOOKUP($A28&X$4,MEN_DES&MEN_COD,MEN_GMS),0)*$Q28} -> 0 | Y28: {=IFERROR(_xlfn.XLOOKUP($A28&Y$4,MEN_DES&MEN_COD,MEN_GMS),0)*$Q28} -> 0 | ... AE28: {=IFERROR(_xlfn.XLOOKUP($A28&AE$4,MEN_DES&MEN_COD,MEN_GMS),0)*$Q28} -> 0 | AG28: {=IFERROR(_xlfn.XLOOKUP($A28&AG$4,MEN_DES&MEN_COD,MEN_GMS),0)*$Q28} -> 0 | AH28: {=IFERROR(_xlfn.XLOOKUP($A28&AH$4,MEN_DES&MEN_COD,MEN_GMS),0)*$Q28} -> 0 | AI28: {=IFERROR(_xlfn.XLOOKUP($A28&AI$4,MEN_DES&MEN_COD,MEN_GMS),0)*$Q28} -> 0 | AJ28: {=IFERROR(_xlfn.XLOOKUP($A28&AJ$4,MEN_DES&MEN_COD,MEN_GMS),0)*$Q28} -> 0 | AK28: {=IFERROR(_xlfn.XLOOKUP($A28&AK$4,MEN_DES&MEN_COD,MEN_GMS),0)*$Q28} -> 0 | AL28: {=IFERROR(_xlfn.XLOOKUP($A28&AL$4,MEN_DES&MEN_COD,MEN_GMS),0)*$Q28} -> 0 | AM28: {=IFERROR(_xlfn.XLOOKUP($A28&AM$4,MEN_DES&MEN_COD,MEN_GMS),0)*$Q28} -> 0 | AN28: {=IFERROR(_xlfn.XLOOKUP($A28&AN$4,MEN_DES&MEN_COD,MEN_GMS),0)*$Q28} -> 0 | ... BN28: {=IFERROR(_xlfn.XLOOKUP($A28&BN$4,MEN_DES&MEN_COD,MEN_GMS),0)*$Q28} -> 0 | BO28: =SUM(R28:BN28) -> 0
R29: {=IFERROR(_xlfn.XLOOKUP($A29&R$4,MEN_DES&MEN_COD,MEN_GMS),0)*$Q29} -> 0 | S29: {=IFERROR(_xlfn.XLOOKUP($A29&S$4,MEN_DES&MEN_COD,MEN_GMS),0)*$Q29} -> 0 | T29: {=IFERROR(_xlfn.XLOOKUP($A29&T$4,MEN_DES&MEN_COD,MEN_GMS),0)*$Q29} -> 0 | U29: {=IFERROR(_xlfn.XLOOKUP($A29&U$4,MEN_DES&MEN_COD,MEN_GMS),0)*$Q29} -> 0 | V29: {=IFERROR(_xlfn.XLOOKUP($A29&V$4,MEN_DES&MEN_COD,MEN_GMS),0)*$Q29} -> 0 | W29: {=IFERROR(_xlfn.XLOOKUP($A29&W$4,MEN_DES&MEN_COD,MEN_GMS),0)*$Q29} -> 0 | X29: {=IFERROR(_xlfn.XLOOKUP($A29&X$4,MEN_DES&MEN_COD,MEN_GMS),0)*$Q29} -> 0 | Y29: {=IFERROR(_xlfn.XLOOKUP($A29&Y$4,MEN_DES&MEN_COD,MEN_GMS),0)*$Q29} -> 0 | ... AE29: {=IFERROR(_xlfn.XLOOKUP($A29&AE$4,MEN_DES&MEN_COD,MEN_GMS),0)*$Q29} -> 0 | AG29: {=IFERROR(_xlfn.XLOOKUP($A29&AG$4,MEN_DES&MEN_COD,MEN_GMS),0)*$Q29} -> 0 | AH29: {=IFERROR(_xlfn.XLOOKUP($A29&AH$4,MEN_DES&MEN_COD,MEN_GMS),0)*$Q29} -> 0 | AI29: {=IFERROR(_xlfn.XLOOKUP($A29&AI$4,MEN_DES&MEN_COD,MEN_GMS),0)*$Q29} -> 0 | AJ29: {=IFERROR(_xlfn.XLOOKUP($A29&AJ$4,MEN_DES&MEN_COD,MEN_GMS),0)*$Q29} -> 0 | AK29: {=IFERROR(_xlfn.XLOOKUP($A29&AK$4,MEN_DES&MEN_COD,MEN_GMS),0)*$Q29} -> 0 | AL29: {=IFERROR(_xlfn.XLOOKUP($A29&AL$4,MEN_DES&MEN_COD,MEN_GMS),0)*$Q29} -> 0 | AM29: {=IFERROR(_xlfn.XLOOKUP($A29&AM$4,MEN_DES&MEN_COD,MEN_GMS),0)*$Q29} -> 0 | AN29: {=IFERROR(_xlfn.XLOOKUP($A29&AN$4,MEN_DES&MEN_COD,MEN_GMS),0)*$Q29} -> 0 | ... BN29: {=IFERROR(_xlfn.XLOOKUP($A29&BN$4,MEN_DES&MEN_COD,MEN_GMS),0)*$Q29} -> 0 | BO29: =SUM(R29:BN29) -> 0
R30: {=IFERROR(_xlfn.XLOOKUP($A30&R$4,MEN_DES&MEN_COD,MEN_GMS),0)*$Q30} -> 0 | S30: {=IFERROR(_xlfn.XLOOKUP($A30&S$4,MEN_DES&MEN_COD,MEN_GMS),0)*$Q30} -> 0 | T30: {=IFERROR(_xlfn.XLOOKUP($A30&T$4,MEN_DES&MEN_COD,MEN_GMS),0)*$Q30} -> 0 | U30: {=IFERROR(_xlfn.XLOOKUP($A30&U$4,MEN_DES&MEN_COD,MEN_GMS),0)*$Q30} -> 0 | V30: {=IFERROR(_xlfn.XLOOKUP($A30&V$4,MEN_DES&MEN_COD,MEN_GMS),0)*$Q30} -> 0 | W30: {=IFERROR(_xlfn.XLOOKUP($A30&W$4,MEN_DES&MEN_COD,MEN_GMS),0)*$Q30} -> 0 | X30: {=IFERROR(_xlfn.XLOOKUP($A30&X$4,MEN_DES&MEN_COD,MEN_GMS),0)*$Q30} -> 0 | Y30: {=IFERROR(_xlfn.XLOOKUP($A30&Y$4,MEN_DES&MEN_COD,MEN_GMS),0)*$Q30} -> 0 | ... AE30: {=IFERROR(_xlfn.XLOOKUP($A30&AE$4,MEN_DES&MEN_COD,MEN_GMS),0)*$Q30} -> 0 | AG30: {=IFERROR(_xlfn.XLOOKUP($A30&AG$4,MEN_DES&MEN_COD,MEN_GMS),0)*$Q30} -> 0 | AH30: {=IFERROR(_xlfn.XLOOKUP($A30&AH$4,MEN_DES&MEN_COD,MEN_GMS),0)*$Q30} -> 0 | AI30: {=IFERROR(_xlfn.XLOOKUP($A30&AI$4,MEN_DES&MEN_COD,MEN_GMS),0)*$Q30} -> 0 | AJ30: {=IFERROR(_xlfn.XLOOKUP($A30&AJ$4,MEN_DES&MEN_COD,MEN_GMS),0)*$Q30} -> 0 | AK30: {=IFERROR(_xlfn.XLOOKUP($A30&AK$4,MEN_DES&MEN_COD,MEN_GMS),0)*$Q30} -> 0 | AL30: {=IFERROR(_xlfn.XLOOKUP($A30&AL$4,MEN_DES&MEN_COD,MEN_GMS),0)*$Q30} -> 0 | AM30: {=IFERROR(_xlfn.XLOOKUP($A30&AM$4,MEN_DES&MEN_COD,MEN_GMS),0)*$Q30} -> 0 | AN30: {=IFERROR(_xlfn.XLOOKUP($A30&AN$4,MEN_DES&MEN_COD,MEN_GMS),0)*$Q30} -> 0 | ... BN30: {=IFERROR(_xlfn.XLOOKUP($A30&BN$4,MEN_DES&MEN_COD,MEN_GMS),0)*$Q30} -> 0 | BO30: =SUM(R30:BN30) -> 0
R31: {=IFERROR(_xlfn.XLOOKUP($A31&R$4,MEN_DES&MEN_COD,MEN_GMS),0)*$Q31} -> 0 | S31: {=IFERROR(_xlfn.XLOOKUP($A31&S$4,MEN_DES&MEN_COD,MEN_GMS),0)*$Q31} -> 0 | T31: {=IFERROR(_xlfn.XLOOKUP($A31&T$4,MEN_DES&MEN_COD,MEN_GMS),0)*$Q31} -> 0 | U31: {=IFERROR(_xlfn.XLOOKUP($A31&U$4,MEN_DES&MEN_COD,MEN_GMS),0)*$Q31} -> 0 | V31: {=IFERROR(_xlfn.XLOOKUP($A31&V$4,MEN_DES&MEN_COD,MEN_GMS),0)*$Q31} -> 0 | W31: {=IFERROR(_xlfn.XLOOKUP($A31&W$4,MEN_DES&MEN_COD,MEN_GMS),0)*$Q31} -> 0 | X31: {=IFERROR(_xlfn.XLOOKUP($A31&X$4,MEN_DES&MEN_COD,MEN_GMS),0)*$Q31} -> 0 | Y31: {=IFERROR(_xlfn.XLOOKUP($A31&Y$4,MEN_DES&MEN_COD,MEN_GMS),0)*$Q31} -> 0 | ... AE31: {=IFERROR(_xlfn.XLOOKUP($A31&AE$4,MEN_DES&MEN_COD,MEN_GMS),0)*$Q31} -> 0 | AG31: {=IFERROR(_xlfn.XLOOKUP($A31&AG$4,MEN_DES&MEN_COD,MEN_GMS),0)*$Q31} -> 0 | AH31: {=IFERROR(_xlfn.XLOOKUP($A31&AH$4,MEN_DES&MEN_COD,MEN_GMS),0)*$Q31} -> 0 | AI31: {=IFERROR(_xlfn.XLOOKUP($A31&AI$4,MEN_DES&MEN_COD,MEN_GMS),0)*$Q31} -> 0 | AJ31: {=IFERROR(_xlfn.XLOOKUP($A31&AJ$4,MEN_DES&MEN_COD,MEN_GMS),0)*$Q31} -> 0 | AK31: {=IFERROR(_xlfn.XLOOKUP($A31&AK$4,MEN_DES&MEN_COD,MEN_GMS),0)*$Q31} -> 0 | AL31: {=IFERROR(_xlfn.XLOOKUP($A31&AL$4,MEN_DES&MEN_COD,MEN_GMS),0)*$Q31} -> 0 | AM31: {=IFERROR(_xlfn.XLOOKUP($A31&AM$4,MEN_DES&MEN_COD,MEN_GMS),0)*$Q31} -> 0 | AN31: {=IFERROR(_xlfn.XLOOKUP($A31&AN$4,MEN_DES&MEN_COD,MEN_GMS),0)*$Q31} -> 0 | ... BN31: {=IFERROR(_xlfn.XLOOKUP($A31&BN$4,MEN_DES&MEN_COD,MEN_GMS),0)*$Q31} -> 0 | BO31: =SUM(R31:BN31) -> 0
R32: {=IFERROR(_xlfn.XLOOKUP($A32&R$4,MEN_DES&MEN_COD,MEN_GMS),0)*$Q32} -> 0 | S32: {=IFERROR(_xlfn.XLOOKUP($A32&S$4,MEN_DES&MEN_COD,MEN_GMS),0)*$Q32} -> 0 | T32: {=IFERROR(_xlfn.XLOOKUP($A32&T$4,MEN_DES&MEN_COD,MEN_GMS),0)*$Q32} -> 0 | U32: {=IFERROR(_xlfn.XLOOKUP($A32&U$4,MEN_DES&MEN_COD,MEN_GMS),0)*$Q32} -> 0 | V32: {=IFERROR(_xlfn.XLOOKUP($A32&V$4,MEN_DES&MEN_COD,MEN_GMS),0)*$Q32} -> 0 | W32: {=IFERROR(_xlfn.XLOOKUP($A32&W$4,MEN_DES&MEN_COD,MEN_GMS),0)*$Q32} -> 0 | X32: {=IFERROR(_xlfn.XLOOKUP($A32&X$4,MEN_DES&MEN_COD,MEN_GMS),0)*$Q32} -> 0 | Y32: {=IFERROR(_xlfn.XLOOKUP($A32&Y$4,MEN_DES&MEN_COD,MEN_GMS),0)*$Q32} -> 0 | ... AE32: {=IFERROR(_xlfn.XLOOKUP($A32&AE$4,MEN_DES&MEN_COD,MEN_GMS),0)*$Q32} -> 0 | AG32: {=IFERROR(_xlfn.XLOOKUP($A32&AG$4,MEN_DES&MEN_COD,MEN_GMS),0)*$Q32} -> 0 | AH32: {=IFERROR(_xlfn.XLOOKUP($A32&AH$4,MEN_DES&MEN_COD,MEN_GMS),0)*$Q32} -> 0 | AI32: {=IFERROR(_xlfn.XLOOKUP($A32&AI$4,MEN_DES&MEN_COD,MEN_GMS),0)*$Q32} -> 0 | AJ32: {=IFERROR(_xlfn.XLOOKUP($A32&AJ$4,MEN_DES&MEN_COD,MEN_GMS),0)*$Q32} -> 0 | AK32: {=IFERROR(_xlfn.XLOOKUP($A32&AK$4,MEN_DES&MEN_COD,MEN_GMS),0)*$Q32} -> 0 | AL32: {=IFERROR(_xlfn.XLOOKUP($A32&AL$4,MEN_DES&MEN_COD,MEN_GMS),0)*$Q32} -> 0 | AM32: {=IFERROR(_xlfn.XLOOKUP($A32&AM$4,MEN_DES&MEN_COD,MEN_GMS),0)*$Q32} -> 0 | AN32: {=IFERROR(_xlfn.XLOOKUP($A32&AN$4,MEN_DES&MEN_COD,MEN_GMS),0)*$Q32} -> 0 | ... BN32: {=IFERROR(_xlfn.XLOOKUP($A32&BN$4,MEN_DES&MEN_COD,MEN_GMS),0)*$Q32} -> 0 | BO32: =SUM(R32:BN32) -> 0
... R223: {=IFERROR(_xlfn.XLOOKUP($A223&R$4,MEN_DES&MEN_COD,MEN_GMS),0)*$Q223} -> 0 | S223: {=IFERROR(_xlfn.XLOOKUP($A223&S$4,MEN_DES&MEN_COD,MEN_GMS),0)*$Q223} -> 0 | T223: {=IFERROR(_xlfn.XLOOKUP($A223&T$4,MEN_DES&MEN_COD,MEN_GMS),0)*$Q223} -> 0 | U223: {=IFERROR(_xlfn.XLOOKUP($A223&U$4,MEN_DES&MEN_COD,MEN_GMS),0)*$Q223} -> 0 | V223: {=IFERROR(_xlfn.XLOOKUP($A223&V$4,MEN_DES&MEN_COD,MEN_GMS),0)*$Q223} -> 0 | W223: {=IFERROR(_xlfn.XLOOKUP($A223&W$4,MEN_DES&MEN_COD,MEN_GMS),0)*$Q223} -> 0 | X223: {=IFERROR(_xlfn.XLOOKUP($A223&X$4,MEN_DES&MEN_COD,MEN_GMS),0)*$Q223} -> 0 | Y223: {=IFERROR(_xlfn.XLOOKUP($A223&Y$4,MEN_DES&MEN_COD,MEN_GMS),0)*$Q223} -> 0 | ... AE223: {=IFERROR(_xlfn.XLOOKUP($A223&AE$4,MEN_DES&MEN_COD,MEN_GMS),0)*$Q223} -> 0 | AG223: {=IFERROR(_xlfn.XLOOKUP($A223&AG$4,MEN_DES&MEN_COD,MEN_GMS),0)*$Q223} -> 0 | AH223: {=IFERROR(_xlfn.XLOOKUP($A223&AH$4,MEN_DES&MEN_COD,MEN_GMS),0)*$Q223} -> 0 | AI223: {=IFERROR(_xlfn.XLOOKUP($A223&AI$4,MEN_DES&MEN_COD,MEN_GMS),0)*$Q223} -> 0 | AJ223: {=IFERROR(_xlfn.XLOOKUP($A223&AJ$4,MEN_DES&MEN_COD,MEN_GMS),0)*$Q223} -> 0 | AK223: {=IFERROR(_xlfn.XLOOKUP($A223&AK$4,MEN_DES&MEN_COD,MEN_GMS),0)*$Q223} -> 0 | AL223: {=IFERROR(_xlfn.XLOOKUP($A223&AL$4,MEN_DES&MEN_COD,MEN_GMS),0)*$Q223} -> 0 | AM223: {=IFERROR(_xlfn.XLOOKUP($A223&AM$4,MEN_DES&MEN_COD,MEN_GMS),0)*$Q223} -> 0 | AN223: {=IFERROR(_xlfn.XLOOKUP($A223&AN$4,MEN_DES&MEN_COD,MEN_GMS),0)*$Q223} -> 0 | ... BN223: {=IFERROR(_xlfn.XLOOKUP($A223&BN$4,MEN_DES&MEN_COD,MEN_GMS),0)*$Q223} -> 0 | BO223: =SUM(R223:BN223) -> 0

Sheet SALES'26
A1: Item name | B1: SKU | C1: Category | D1: Items sold | E1: Gross sales | F1: Items refunded | G1: Refunds | H1: Discounts | I1: Net sales | J1: Cost of goods | K1: Gross profit | L1: Margin | M1: Taxes | N1: DATE
A2: [ATF] Beef Teriyaki Noodles (Regular) | B2: 10457 | C2: ALL TIME FAVORITES | D2: 1 | E2: 285 | F2: 0 | G2: 0 | H2: 0 | I2: 285 | J2: 0 | K2: 285 | L2: 1 | M2: 0 | N2: 45992
A3: [ATF] Ebi Tempura (6pcs) | B3: 10450 | C3: ALL TIME FAVORITES | D3: 1 | E3: 470 | F3: 0 | G3: 0 | H3: 5.74 | I3: 464.26 | J3: 0 | K3: 464.26 | L3: 1 | M3: 0 | N3: 45992
A4: [DB] Beef Terriyaki (Set B) | B4: 10158 | C4: DON BURI (BEEF) | D4: 1 | E4: 385 | F4: 0 | G4: 0 | H4: 0 | I4: 385 | J4: 0 | K4: 385 | L4: 1 | M4: 0 | N4: 45992
A5: [DB] Karaagedon (A) | B5: 10665 | C5: GRAB FOOD | D5: 1 | E5: 299 | F5: 0 | G5: 0 | H5: 0 | I5: 299 | J5: 0 | K5: 299 | L5: 1 | M5: 0 | N5: 45992
A6: [DB] Katsudon (Set A) | B6: 10109 | C6: DON BURI (PORK) | D6: 1 | E6: 275 | F6: 0 | G6: 0 | H6: 0 | I6: 275 | J6: 0 | K6: 275 | L6: 1 | M6: 0 | N6: 45992
A7: [DB] Oyakudon (Set B) | B7: 10051 | C7: DON BURI (CHICKEN) | D7: 1 | E7: 315 | F7: 0 | G7: 0 | H7: 0 | I7: 315 | J7: 0 | K7: 315 | L7: 1 | M7: 0 | N7: 45992
A8: [DB] Torikatsu (Set A) | B8: 10055 | C8: DON BURI (CHICKEN) | D8: 1 | E8: 260 | F8: 0 | G8: 0 | H8: 0 | I8: 260 | J8: 0 | K8: 260 | L8: 1 | M8: 0 | N8: 45992
A9: [DB] Torikatsudon (Set A) | B9: 10062 | C9: DON BURI (CHICKEN) | D9: 2 | E9: 550 | F9: 0 | G9: 0 | H9: 0 | I9: 550 | J9: 0 | K9: 550 | L9: 1 | M9: 0 | N9: 45992
A10: [MR] California Maki | B10: 10264 | C10: MAKI ROLLS | D10: 1 | E10: 190 | F10: 0 | G10: 0 | H10: 0 | I10: 190 | J10: 0 | K10: 190 | L10: 1 | M10: 0 | N10: 45992
A11: [MR] Cheesy Cowboy | B11: 10366 | C11: MAKI ROLLS | D11: 1 | E11: 270 | F11: 0 | G11: 0 | H11: 0 | I11: 270 | J11: 0 | K11: 270 | L11: 1 | M11: 0 | N11: 45992
A12: [MR] Salmon Mango Roll | B12: 10007 | C12: MAKI ROLLS | D12: 1 | E12: 275 | F12: 0 | G12: 0 | H12: 0 | I12: 275 | J12: 0 | K12: 275 | L12: 1 | M12: 0 | N12: 45992
A13: [RM] Shoyu Seafood Ramen | B13: 10353 | C13: RAMEN BOWLS | D13: 1 | E13: 350 | F13: 0 | G13: 0 | H13: 4.28 | I13: 345.72 | J13: 0 | K13: 345.72 | L13: 1 | M13: 0 | N13: 45992
... A55: [SM] Yakisoba w/ Yakitori (Chicekn BBQ) & Cali Maki | B55: 10037 | C55: SNACK MEALS | D55: 1 | E55: 395 | F55: 0 | G55: 0 | H55: 0 | I55: 395 | J55: 0 | K55: 395 | L55: 1 | M55: 0 | N55: 45993
A56: Caramel choco bliss | B56: 00 | C56: Dessert | D56: 1 | E56: 150 | F56: 0 | G56: 0 | H56: 0 | I56: 150 | J56: 0 | K56: 150 | L56: 1 | M56: 0 | N56: 45993
A57: Ramen soup | B57: 000000 | C57: Other | D57: 1 | E57: 45 | F57: 0 | G57: 0 | H57: 0 | I57: 45 | J57: 0 | K57: 45 | L57: 1 | M57: 0 | N57: 45993
A58: Torikatsudon | B58: 10632 | C58: ANNIVERSARY PROMO 2025 | D58: 2 | E58: 318 | F58: 0 | G58: 0 | H58: 0 | I58: 318 | J58: 0 | K58: 318 | L58: 1 | M58: 0 | N58: 45993
A59: 4pcs California Maki | B59: 1066 | C59: Other | D59: 1 | E59: 99 | F59: 0 | G59: 0 | H59: 0 | I59: 99 | J59: 0 | K59: 99 | L59: 1 | M59: 0 | N59: 45994
A60: [ATF] Ebi Tempura (6pcs) | B60: 10450 | C60: ALL TIME FAVORITES | D60: 1 | E60: 470 | F60: 0 | G60: 0 | H60: 0 | I60: 470 | J60: 0 | K60: 470 | L60: 1 | M60: 0 | N60: 45994
A61: [Baked Sushi] Cheesy Beef | B61: 10575 | C61: MANAGEMENT | D61: 1 | E61: 0 | F61: 0 | G61: 0 | H61: 0 | I61: 0 | J61: 0 | K61: 0 | L61: 0 | M61: 0 | N61: 45994
A62: [BS] Cheesy Beef | B62: 10397 | C62: BAKED SUSHI | D62: 1 | E62: 575 | F62: 0 | G62: 0 | H62: 115 | I62: 460 | J62: 0 | K62: 460 | L62: 1 | M62: 0 | N62: 45994
A63: [DB] Beef Curry (Set A) | B63: 10152 | C63: DON BURI (BEEF) | D63: 1 | E63: 350 | F63: 0 | G63: 0 | H63: 0 | I63: 350 | J63: 0 | K63: 350 | L63: 1 | M63: 0 | N63: 45994
A64: [DB] Beef Teppanyaki/Misono (Set A) | B64: 10167 | C64: DON BURI (BEEF) | D64: 1 | E64: 350 | F64: 0 | G64: 0 | H64: 0 | I64: 350 | J64: 0 | K64: 350 | L64: 1 | M64: 0 | N64: 45994
A65: [DB] Crispy Chicken w/ Egg (Set A) | B65: 10225 | C65: DON BURI (CHICKEN) | D65: 1 | E65: 255 | F65: 0 | G65: 0 | H65: 0 | I65: 255 | J65: 0 | K65: 255 | L65: 1 | M65: 0 | N65: 45994
A66: [DB] Gyudon (Set A) | B66: 10645 | C66: DON BURI (BEEF) | D66: 4 | E66: 1360 | F66: 0 | G66: 0 | H66: 0 | I66: 1360 | J66: 0 | K66: 1360 | L66: 1 | M66: 0 | N66: 45994
A67: [DB] Gyudon (Set B) | B67: 10145 | C67: DON BURI (BEEF) | D67: 1 | E67: 370 | F67: 0 | G67: 0 | H67: 0 | I67: 370 | J67: 0 | K67: 370 | L67: 1 | M67: 0 | N67: 45994
